Workbook

Sheet 사용법
B1: 부의금 정산 양식
B3: 삼가 고인의 명복을 빕니다.
B4: 경황 없으실 텐데, 적기만 하시면 계산은 이 파일이 합니다.
B6: ① '가족 목록' 탭에 부의금을 받는 가족 이름을 적으세요. (최대 20명)
B7: 여럿이 함께 받은 돈은 '공동'이나 '아빠·작은아빠'처럼 이름을 하나 만들어 쓰세요.
B8: ② '부의금 입력' 탭에 한 줄에 한 분씩 적으세요. 받은 가족은 목록에서 고르고, 금액은 숫자로(50000).
B9: ③ 하루가 끝나면 이름 칸에 '1일차 소계', 금액 칸에 그날 합계를 적으세요. 요약 탭에서 맞는지 비교해 줍니다.
B10: 마지막에 '총합계' 줄을 적어도 됩니다. '소계'·'합계' 줄은 합계에 두 번 들어가지 않습니다.
B11: ④ 화환·근조기·바구니는 '근조 화환' 탭, 장례 비용은 '지출' 탭에 적으세요.
B12: 부의금과 따로 모은 공금이 있으면 지출 탭 오른쪽 '공금 시작'에 금액을 넣고, 낸 사람을 '공금'으로 고르세요.
B13: ⑤ '요약' 탭 정산 표 위 노란 칸에서 정산 방법을 고르세요: 똑같이 나누기 / 받은 부의금 비율 / 손님 수 비율.
B14: 방법별 장단점은 요약 표 아래에 있습니다. 비용을 나눠 내지 않을 가족은 '가족 목록'의 '정산 참여'에 X.
... B29: 이 양식은 계산을 편하게 하도록 돕는 도구일 뿐이며, 결과가 정확하다고 보장하지 않습니다. 중요한 금액은 반드시 직접 확인하세요. 이 양식을 쓰거나 그 결과를 근거로 해서 생긴 계산 오류, 금전 정산, 가족·지인 간 분쟁, 그 밖의 어떤 손해에 대해서도 만든 사람은 책임을 지지 않습니다. 법률·세무 자문이 아닙니다.

Sheet 요약
A1: 총 합계 | B1: =SUMIF('부의금 입력'!$G$2:$G$1001,">0",'부의금 입력'!$C$2:$C$1001) | D1: 조화·물품 | E1: =SUM('근조 화환'!$H$2:$H$501) | G1: 장부 총합계 | H1: =IF(COUNTIF('부의금 입력'!$B$2:$B$1001,"*총합계*")=0,"",SUMIF('부의금 입력'!$B$2:$B$1001,"*총합계*",'부의금 입력'!$C$2:$C$1001))
A2: 총 건수 | B2: =COUNTIF('부의금 입력'!$G$2:$G$1001,">0") | D2: 지출 총액 | E2: =지출!H4 | G2: 장부와 차이 | H2: =IF(H1="","",B1-H1)
A3: 확인 필요 | B3: =SUM('부의금 입력'!$J$2:$J$1001)+SUM('근조 화환'!$I$2:$I$501)+SUM(지출!$Y$2:$Y$301) | D3: 남는 돈 | E3: =지출!H5 | G3: 지출 비율 | H3: =IF(B1=0,"-",지출!H4/B1)
G4: 정산 방법 ▶ | H4: ▼ 정산 방법을 골라 주세요 | K4: 일차별 소계 | Q4: =IFERROR(VALUE(LEFT($H$4,1)),0)
A5: 받은 가족 | B5: 건수 | C5: 합계 | D5: 비중 | E5: 조화·물품 | G5: 지출 분담 | H5: 남는 몫 | I5: 실제 지급 | K5: 일차 | L5: 건수 | M5: 합계 | N5: 장부에 적은 소계 | O5: 차이
A6: =IF('가족 목록'!A2="","",'가족 목록'!A2) | B6: =IF($A6="","",COUNTIFS('부의금 입력'!$A$2:$A$1001,$A6,'부의금 입력'!$G$2:$G$1001,">0")) | C6: =IF($A6="","",SUMIFS('부의금 입력'!$C$2:$C$1001,'부의금 입력'!$A$2:$A$1001,$A6,'부의금 입력'!$G$2:$G$1001,">0")) | D6: =IF($A6="","",IF($B$1=0,0,C6/$B$1)) | E6: =IF($A6="","",COUNTIF('근조 화환'!$A$2:$A$501,$A6)) | G6: =IF(OR($A6="",$Q$4=0),"",IF(SUM($R$6:$R$25)=0,0,지출!$H$4*R6/SUM($R$6:$R$25))) | H6: =IF(G6="","",C6-G6) | K6: =IF(1<=MAX('부의금 입력'!$G$2:$G$1001),1,"") | L6: =IF(K6="","",COUNTIF('부의금 입력'!$G$2:$G$1001,K6)) | M6: =IF(K6="","",SUMIF('부의금 입력'!$G$2:$G$1001,K6,'부의금 입력'!$C$2:$C$1001)) | N6: =IF(K6="","",IF(COUNTIF('부의금 입력'!$I$2:$I$1001,K6)=0,"",SUMIF('부의금 입력'!$I$2:$I$1001,K6,'부의금 입력'!$C$2:$C$1001))) | O6: =IF(OR(K6="",N6=""),"",M6-N6) | Q6: =IF($A6="",0,IF(UPPER(TRIM('가족 목록'!B2))="X",0,1)) | R6: =IF(OR(Q6=0,$Q$4=0),0,CHOOSE($Q$4,1,C6,B6))
A7: =IF('가족 목록'!A3="","",'가족 목록'!A3) | B7: =IF($A7="","",COUNTIFS('부의금 입력'!$A$2:$A$1001,$A7,'부의금 입력'!$G$2:$G$1001,">0")) | C7: =IF($A7="","",SUMIFS('부의금 입력'!$C$2:$C$1001,'부의금 입력'!$A$2:$A$1001,$A7,'부의금 입력'!$G$2:$G$1001,">0")) | D7: =IF($A7="","",IF($B$1=0,0,C7/$B$1)) | E7: =IF($A7="","",COUNTIF('근조 화환'!$A$2:$A$501,$A7)) | G7: =IF(OR($A7="",$Q$4=0),"",IF(SUM($R$6:$R$25)=0,0,지출!$H$4*R7/SUM($R$6:$R$25))) | H7: =IF(G7="","",C7-G7) | K7: =IF(2<=MAX('부의금 입력'!$G$2:$G$1001),2,"") | L7: =IF(K7="","",COUNTIF('부의금 입력'!$G$2:$G$1001,K7)) | M7: =IF(K7="","",SUMIF('부의금 입력'!$G$2:$G$1001,K7,'부의금 입력'!$C$2:$C$1001)) | N7: =IF(K7="","",IF(COUNTIF('부의금 입력'!$I$2:$I$1001,K7)=0,"",SUMIF('부의금 입력'!$I$2:$I$1001,K7,'부의금 입력'!$C$2:$C$1001))) | O7: =IF(OR(K7="",N7=""),"",M7-N7) | Q7: =IF($A7="",0,IF(UPPER(TRIM('가족 목록'!B3))="X",0,1)) | R7: =IF(OR(Q7=0,$Q$4=0),0,CHOOSE($Q$4,1,C7,B7))
A8: =IF('가족 목록'!A4="","",'가족 목록'!A4) | B8: =IF($A8="","",COUNTIFS('부의금 입력'!$A$2:$A$1001,$A8,'부의금 입력'!$G$2:$G$1001,">0")) | C8: =IF($A8="","",SUMIFS('부의금 입력'!$C$2:$C$1001,'부의금 입력'!$A$2:$A$1001,$A8,'부의금 입력'!$G$2:$G$1001,">0")) | D8: =IF($A8="","",IF($B$1=0,0,C8/$B$1)) | E8: =IF($A8="","",COUNTIF('근조 화환'!$A$2:$A$501,$A8)) | G8: =IF(OR($A8="",$Q$4=0),"",IF(SUM($R$6:$R$25)=0,0,지출!$H$4*R8/SUM($R$6:$R$25))) | H8: =IF(G8="","",C8-G8) | K8: =IF(3<=MAX('부의금 입력'!$G$2:$G$1001),3,"") | L8: =IF(K8="","",COUNTIF('부의금 입력'!$G$2:$G$1001,K8)) | M8: =IF(K8="","",SUMIF('부의금 입력'!$G$2:$G$1001,K8,'부의금 입력'!$C$2:$C$1001)) | N8: =IF(K8="","",IF(COUNTIF('부의금 입력'!$I$2:$I$1001,K8)=0,"",SUMIF('부의금 입력'!$I$2:$I$1001,K8,'부의금 입력'!$C$2:$C$1001))) | O8: =IF(OR(K8="",N8=""),"",M8-N8) | Q8: =IF($A8="",0,IF(UPPER(TRIM('가족 목록'!B4))="X",0,1)) | R8: =IF(OR(Q8=0,$Q$4=0),0,CHOOSE($Q$4,1,C8,B8))
A9: =IF('가족 목록'!A5="","",'가족 목록'!A5) | B9: =IF($A9="","",COUNTIFS('부의금 입력'!$A$2:$A$1001,$A9,'부의금 입력'!$G$2:$G$1001,">0")) | C9: =IF($A9="","",SUMIFS('부의금 입력'!$C$2:$C$1001,'부의금 입력'!$A$2:$A$1001,$A9,'부의금 입력'!$G$2:$G$1001,">0")) | D9: =IF($A9="","",IF($B$1=0,0,C9/$B$1)) | E9: =IF($A9="","",COUNTIF('근조 화환'!$A$2:$A$501,$A9)) | G9: =IF(OR($A9="",$Q$4=0),"",IF(SUM($R$6:$R$25)=0,0,지출!$H$4*R9/SUM($R$6:$R$25))) | H9: =IF(G9="","",C9-G9) | K9: =IF(4<=MAX('부의금 입력'!$G$2:$G$1001),4,"") | L9: =IF(K9="","",COUNTIF('부의금 입력'!$G$2:$G$1001,K9)) | M9: =IF(K9="","",SUMIF('부의금 입력'!$G$2:$G$1001,K9,'부의금 입력'!$C$2:$C$1001)) | N9: =IF(K9="","",IF(COUNTIF('부의금 입력'!$I$2:$I$1001,K9)=0,"",SUMIF('부의금 입력'!$I$2:$I$1001,K9,'부의금 입력'!$C$2:$C$1001))) | O9: =IF(OR(K9="",N9=""),"",M9-N9) | Q9: =IF($A9="",0,IF(UPPER(TRIM('가족 목록'!B5))="X",0,1)) | R9: =IF(OR(Q9=0,$Q$4=0),0,CHOOSE($Q$4,1,C9,B9))
A10: =IF('가족 목록'!A6="","",'가족 목록'!A6) | B10: =IF($A10="","",COUNTIFS('부의금 입력'!$A$2:$A$1001,$A10,'부의금 입력'!$G$2:$G$1001,">0")) | C10: =IF($A10="","",SUMIFS('부의금 입력'!$C$2:$C$1001,'부의금 입력'!$A$2:$A$1001,$A10,'부의금 입력'!$G$2:$G$1001,">0")) | D10: =IF($A10="","",IF($B$1=0,0,C10/$B$1)) | E10: =IF($A10="","",COUNTIF('근조 화환'!$A$2:$A$501,$A10)) | G10: =IF(OR($A10="",$Q$4=0),"",IF(SUM($R$6:$R$25)=0,0,지출!$H$4*R10/SUM($R$6:$R$25))) | H10: =IF(G10="","",C10-G10) | K10: =IF(5<=MAX('부의금 입력'!$G$2:$G$1001),5,"") | L10: =IF(K10="","",COUNTIF('부의금 입력'!$G$2:$G$1001,K10)) | M10: =IF(K10="","",SUMIF('부의금 입력'!$G$2:$G$1001,K10,'부의금 입력'!$C$2:$C$1001)) | N10: =IF(K10="","",IF(COUNTIF('부의금 입력'!$I$2:$I$1001,K10)=0,"",SUMIF('부의금 입력'!$I$2:$I$1001,K10,'부의금 입력'!$C$2:$C$1001))) | O10: =IF(OR(K10="",N10=""),"",M10-N10) | Q10: =IF($A10="",0,IF(UPPER(TRIM('가족 목록'!B6))="X",0,1)) | R10: =IF(OR(Q10=0,$Q$4=0),0,CHOOSE($Q$4,1,C10,B10))
A11: =IF('가족 목록'!A7="","",'가족 목록'!A7) | B11: =IF($A11="","",COUNTIFS('부의금 입력'!$A$2:$A$1001,$A11,'부의금 입력'!$G$2:$G$1001,">0")) | C11: =IF($A11="","",SUMIFS('부의금 입력'!$C$2:$C$1001,'부의금 입력'!$A$2:$A$1001,$A11,'부의금 입력'!$G$2:$G$1001,">0")) | D11: =IF($A11="","",IF($B$1=0,0,C11/$B$1)) | E11: =IF($A11="","",COUNTIF('근조 화환'!$A$2:$A$501,$A11)) | G11: =IF(OR($A11="",$Q$4=0),"",IF(SUM($R$6:$R$25)=0,0,지출!$H$4*R11/SUM($R$6:$R$25))) | H11: =IF(G11="","",C11-G11) | K11: =IF(6<=MAX('부의금 입력'!$G$2:$G$1001),6,"") | L11: =IF(K11="","",COUNTIF('부의금 입력'!$G$2:$G$1001,K11)) | M11: =IF(K11="","",SUMIF('부의금 입력'!$G$2:$G$1001,K11,'부의금 입력'!$C$2:$C$1001)) | N11: =IF(K11="","",IF(COUNTIF('부의금 입력'!$I$2:$I$1001,K11)=0,"",SUMIF('부의금 입력'!$I$2:$I$1001,K11,'부의금 입력'!$C$2:$C$1001))) | O11: =IF(OR(K11="",N11=""),"",M11-N11) | Q11: =IF($A11="",0,IF(UPPER(TRIM('가족 목록'!B7))="X",0,1)) | R11: =IF(OR(Q11=0,$Q$4=0),0,CHOOSE($Q$4,1,C11,B11))
A12: =IF('가족 목록'!A8="","",'가족 목록'!A8) | B12: =IF($A12="","",COUNTIFS('부의금 입력'!$A$2:$A$1001,$A12,'부의금 입력'!$G$2:$G$1001,">0")) | C12: =IF($A12="","",SUMIFS('부의금 입력'!$C$2:$C$1001,'부의금 입력'!$A$2:$A$1001,$A12,'부의금 입력'!$G$2:$G$1001,">0")) | D12: =IF($A12="","",IF($B$1=0,0,C12/$B$1)) | E12: =IF($A12="","",COUNTIF('근조 화환'!$A$2:$A$501,$A12)) | G12: =IF(OR($A12="",$Q$4=0),"",IF(SUM($R$6:$R$25)=0,0,지출!$H$4*R12/SUM($R$6:$R$25))) | H12: =IF(G12="","",C12-G12) | K12: =IF(7<=MAX('부의금 입력'!$G$2:$G$1001),7,"") | L12: =IF(K12="","",COUNTIF('부의금 입력'!$G$2:$G$1001,K12)) | M12: =IF(K12="","",SUMIF('부의금 입력'!$G$2:$G$1001,K12,'부의금 입력'!$C$2:$C$1001)) | N12: =IF(K12="","",IF(COUNTIF('부의금 입력'!$I$2:$I$1001,K12)=0,"",SUMIF('부의금 입력'!$I$2:$I$1001,K12,'부의금 입력'!$C$2:$C$1001))) | O12: =IF(OR(K12="",N12=""),"",M12-N12) | Q12: =IF($A12="",0,IF(UPPER(TRIM('가족 목록'!B8))="X",0,1)) | R12: =IF(OR(Q12=0,$Q$4=0),0,CHOOSE($Q$4,1,C12,B12))
A13: =IF('가족 목록'!A9="","",'가족 목록'!A9) | B13: =IF($A13="","",COUNTIFS('부의금 입력'!$A$2:$A$1001,$A13,'부의금 입력'!$G$2:$G$1001,">0")) | C13: =IF($A13="","",SUMIFS('부의금 입력'!$C$2:$C$1001,'부의금 입력'!$A$2:$A$1001,$A13,'부의금 입력'!$G$2:$G$1001,">0")) | D13: =IF($A13="","",IF($B$1=0,0,C13/$B$1)) | E13: =IF($A13="","",COUNTIF('근조 화환'!$A$2:$A$501,$A13)) | G13: =IF(OR($A13="",$Q$4=0),"",IF(SUM($R$6:$R$25)=0,0,지출!$H$4*R13/SUM($R$6:$R$25))) | H13: =IF(G13="","",C13-G13) | K13: =IF(8<=MAX('부의금 입력'!$G$2:$G$1001),8,"") | L13: =IF(K13="","",COUNTIF('부의금 입력'!$G$2:$G$1001,K13)) | M13: =IF(K13="","",SUMIF('부의금 입력'!$G$2:$G$1001,K13,'부의금 입력'!$C$2:$C$1001)) | N13: =IF(K13="","",IF(COUNTIF('부의금 입력'!$I$2:$I$1001,K13)=0,"",SUMIF('부의금 입력'!$I$2:$I$1001,K13,'부의금 입력'!$C$2:$C$1001))) | O13: =IF(OR(K13="",N13=""),"",M13-N13) | Q13: =IF($A13="",0,IF(UPPER(TRIM('가족 목록'!B9))="X",0,1)) | R13: =IF(OR(Q13=0,$Q$4=0),0,CHOOSE($Q$4,1,C13,B13))
A14: =IF('가족 목록'!A10="","",'가족 목록'!A10) | B14: =IF($A14="","",COUNTIFS('부의금 입력'!$A$2:$A$1001,$A14,'부의금 입력'!$G$2:$G$1001,">0")) | C14: =IF($A14="","",SUMIFS('부의금 입력'!$C$2:$C$1001,'부의금 입력'!$A$2:$A$1001,$A14,'부의금 입력'!$G$2:$G$1001,">0")) | D14: =IF($A14="","",IF($B$1=0,0,C14/$B$1)) | E14: =IF($A14="","",COUNTIF('근조 화환'!$A$2:$A$501,$A14)) | G14: =IF(OR($A14="",$Q$4=0),"",IF(SUM($R$6:$R$25)=0,0,지출!$H$4*R14/SUM($R$6:$R$25))) | H14: =IF(G14="","",C14-G14) | K14: =IF(9<=MAX('부의금 입력'!$G$2:$G$1001),9,"") | L14: =IF(K14="","",COUNTIF('부의금 입력'!$G$2:$G$1001,K14)) | M14: =IF(K14="","",SUMIF('부의금 입력'!$G$2:$G$1001,K14,'부의금 입력'!$C$2:$C$1001)) | N14: =IF(K14="","",IF(COUNTIF('부의금 입력'!$I$2:$I$1001,K14)=0,"",SUMIF('부의금 입력'!$I$2:$I$1001,K14,'부의금 입력'!$C$2:$C$1001))) | O14: =IF(OR(K14="",N14=""),"",M14-N14) | Q14: =IF($A14="",0,IF(UPPER(TRIM('가족 목록'!B10))="X",0,1)) | R14: =IF(OR(Q14=0,$Q$4=0),0,CHOOSE($Q$4,1,C14,B14))
A15: =IF('가족 목록'!A11="","",'가족 목록'!A11) | B15: =IF($A15="","",COUNTIFS('부의금 입력'!$A$2:$A$1001,$A15,'부의금 입력'!$G$2:$G$1001,">0")) | C15: =IF($A15="","",SUMIFS('부의금 입력'!$C$2:$C$1001,'부의금 입력'!$A$2:$A$1001,$A15,'부의금 입력'!$G$2:$G$1001,">0")) | D15: =IF($A15="","",IF($B$1=0,0,C15/$B$1)) | E15: =IF($A15="","",COUNTIF('근조 화환'!$A$2:$A$501,$A15)) | G15: =IF(OR($A15="",$Q$4=0),"",IF(SUM($R$6:$R$25)=0,0,지출!$H$4*R15/SUM($R$6:$R$25))) | H15: =IF(G15="","",C15-G15) | K15: =IF(10<=MAX('부의금 입력'!$G$2:$G$1001),10,"") | L15: =IF(K15="","",COUNTIF('부의금 입력'!$G$2:$G$1001,K15)) | M15: =IF(K15="","",SUMIF('부의금 입력'!$G$2:$G$1001,K15,'부의금 입력'!$C$2:$C$1001)) | N15: =IF(K15="","",IF(COUNTIF('부의금 입력'!$I$2:$I$1001,K15)=0,"",SUMIF('부의금 입력'!$I$2:$I$1001,K15,'부의금 입력'!$C$2:$C$1001))) | O15: =IF(OR(K15="",N15=""),"",M15-N15) | Q15: =IF($A15="",0,IF(UPPER(TRIM('가족 목록'!B11))="X",0,1)) | R15: =IF(OR(Q15=0,$Q$4=0),0,CHOOSE($Q$4,1,C15,B15))
A16: =IF('가족 목록'!A12="","",'가족 목록'!A12) | B16: =IF($A16="","",COUNTIFS('부의금 입력'!$A$2:$A$1001,$A16,'부의금 입력'!$G$2:$G$1001,">0")) | C16: =IF($A16="","",SUMIFS('부의금 입력'!$C$2:$C$1001,'부의금 입력'!$A$2:$A$1001,$A16,'부의금 입력'!$G$2:$G$1001,">0")) | D16: =IF($A16="","",IF($B$1=0,0,C16/$B$1)) | E16: =IF($A16="","",COUNTIF('근조 화환'!$A$2:$A$501,$A16)) | G16: =IF(OR($A16="",$Q$4=0),"",IF(SUM($R$6:$R$25)=0,0,지출!$H$4*R16/SUM($R$6:$R$25))) | H16: =IF(G16="","",C16-G16) | Q16: =IF($A16="",0,IF(UPPER(TRIM('가족 목록'!B12))="X",0,1)) | R16: =IF(OR(Q16=0,$Q$4=0),0,CHOOSE($Q$4,1,C16,B16))
A17: =IF('가족 목록'!A13="","",'가족 목록'!A13) | B17: =IF($A17="","",COUNTIFS('부의금 입력'!$A$2:$A$1001,$A17,'부의금 입력'!$G$2:$G$1001,">0")) | C17: =IF($A17="","",SUMIFS('부의금 입력'!$C$2:$C$1001,'부의금 입력'!$A$2:$A$1001,$A17,'부의금 입력'!$G$2:$G$1001,">0")) | D17: =IF($A17="","",IF($B$1=0,0,C17/$B$1)) | E17: =IF($A17="","",COUNTIF('근조 화환'!$A$2:$A$501,$A17)) | G17: =IF(OR($A17="",$Q$4=0),"",IF(SUM($R$6:$R$25)=0,0,지출!$H$4*R17/SUM($R$6:$R$25))) | H17: =IF(G17="","",C17-G17) | Q17: =IF($A17="",0,IF(UPPER(TRIM('가족 목록'!B13))="X",0,1)) | R17: =IF(OR(Q17=0,$Q$4=0),0,CHOOSE($Q$4,1,C17,B17))
A18: =IF('가족 목록'!A14="","",'가족 목록'!A14) | B18: =IF($A18="","",COUNTIFS('부의금 입력'!$A$2:$A$1001,$A18,'부의금 입력'!$G$2:$G$1001,">0")) | C18: =IF($A18="","",SUMIFS('부의금 입력'!$C$2:$C$1001,'부의금 입력'!$A$2:$A$1001,$A18,'부의금 입력'!$G$2:$G$1001,">0")) | D18: =IF($A18="","",IF($B$1=0,0,C18/$B$1)) | E18: =IF($A18="","",COUNTIF('근조 화환'!$A$2:$A$501,$A18)) | G18: =IF(OR($A18="",$Q$4=0),"",IF(SUM($R$6:$R$25)=0,0,지출!$H$4*R18/SUM($R$6:$R$25))) | H18: =IF(G18="","",C18-G18) | Q18: =IF($A18="",0,IF(UPPER(TRIM('가족 목록'!B14))="X",0,1)) | R18: =IF(OR(Q18=0,$Q$4=0),0,CHOOSE($Q$4,1,C18,B18))
A19: =IF('가족 목록'!A15="","",'가족 목록'!A15) | B19: =IF($A19="","",COUNTIFS('부의금 입력'!$A$2:$A$1001,$A19,'부의금 입력'!$G$2:$G$1001,">0")) | C19: =IF($A19="","",SUMIFS('부의금 입력'!$C$2:$C$1001,'부의금 입력'!$A$2:$A$1001,$A19,'부의금 입력'!$G$2:$G$1001,">0")) | D19: =IF($A19="","",IF($B$1=0,0,C19/$B$1)) | E19: =IF($A19="","",COUNTIF('근조 화환'!$A$2:$A$501,$A19)) | G19: =IF(OR($A19="",$Q$4=0),"",IF(SUM($R$6:$R$25)=0,0,지출!$H$4*R19/SUM($R$6:$R$25))) | H19: =IF(G19="","",C19-G19) | Q19: =IF($A19="",0,IF(UPPER(TRIM('가족 목록'!B15))="X",0,1)) | R19: =IF(OR(Q19=0,$Q$4=0),0,CHOOSE($Q$4,1,C19,B19))
A20: =IF('가족 목록'!A16="","",'가족 목록'!A16) | B20: =IF($A20="","",COUNTIFS('부의금 입력'!$A$2:$A$1001,$A20,'부의금 입력'!$G$2:$G$1001,">0")) | C20: =IF($A20="","",SUMIFS('부의금 입력'!$C$2:$C$1001,'부의금 입력'!$A$2:$A$1001,$A20,'부의금 입력'!$G$2:$G$1001,">0")) | D20: =IF($A20="","",IF($B$1=0,0,C20/$B$1)) | E20: =IF($A20="","",COUNTIF('근조 화환'!$A$2:$A$501,$A20)) | G20: =IF(OR($A20="",$Q$4=0),"",IF(SUM($R$6:$R$25)=0,0,지출!$H$4*R20/SUM($R$6:$R$25))) | H20: =IF(G20="","",C20-G20) | Q20: =IF($A20="",0,IF(UPPER(TRIM('가족 목록'!B16))="X",0,1)) | R20: =IF(OR(Q20=0,$Q$4=0),0,CHOOSE($Q$4,1,C20,B20))
A21: =IF('가족 목록'!A17="","",'가족 목록'!A17) | B21: =IF($A21="","",COUNTIFS('부의금 입력'!$A$2:$A$1001,$A21,'부의금 입력'!$G$2:$G$1001,">0")) | C21: =IF($A21="","",SUMIFS('부의금 입력'!$C$2:$C$1001,'부의금 입력'!$A$2:$A$1001,$A21,'부의금 입력'!$G$2:$G$1001,">0")) | D21: =IF($A21="","",IF($B$1=0,0,C21/$B$1)) | E21: =IF($A21="","",COUNTIF('근조 화환'!$A$2:$A$501,$A21)) | G21: =IF(OR($A21="",$Q$4=0),"",IF(SUM($R$6:$R$25)=0,0,지출!$H$4*R21/SUM($R$6:$R$25))) | H21: =IF(G21="","",C21-G21) | Q21: =IF($A21="",0,IF(UPPER(TRIM('가족 목록'!B17))="X",0,1)) | R21: =IF(OR(Q21=0,$Q$4=0),0,CHOOSE($Q$4,1,C21,B21))
A22: =IF('가족 목록'!A18="","",'가족 목록'!A18) | B22: =IF($A22="","",COUNTIFS('부의금 입력'!$A$2:$A$1001,$A22,'부의금 입력'!$G$2:$G$1001,">0")) | C22: =IF($A22="","",SUMIFS('부의금 입력'!$C$2:$C$1001,'부의금 입력'!$A$2:$A$1001,$A22,'부의금 입력'!$G$2:$G$1001,">0")) | D22: =IF($A22="","",IF($B$1=0,0,C22/$B$1)) | E22: =IF($A22="","",COUNTIF('근조 화환'!$A$2:$A$501,$A22)) | G22: =IF(OR($A22="",$Q$4=0),"",IF(SUM($R$6:$R$25)=0,0,지출!$H$4*R22/SUM($R$6:$R$25))) | H22: =IF(G22="","",C22-G22) | Q22: =IF($A22="",0,IF(UPPER(TRIM('가족 목록'!B18))="X",0,1)) | R22: =IF(OR(Q22=0,$Q$4=0),0,CHOOSE($Q$4,1,C22,B22))
A23: =IF('가족 목록'!A19="","",'가족 목록'!A19) | B23: =IF($A23="","",COUNTIFS('부의금 입력'!$A$2:$A$1001,$A23,'부의금 입력'!$G$2:$G$1001,">0")) | C23: =IF($A23="","",SUMIFS('부의금 입력'!$C$2:$C$1001,'부의금 입력'!$A$2:$A$1001,$A23,'부의금 입력'!$G$2:$G$1001,">0")) | D23: =IF($A23="","",IF($B$1=0,0,C23/$B$1)) | E23: =IF($A23="","",COUNTIF('근조 화환'!$A$2:$A$501,$A23)) | G23: =IF(OR($A23="",$Q$4=0),"",IF(SUM($R$6:$R$25)=0,0,지출!$H$4*R23/SUM($R$6:$R$25))) | H23: =IF(G23="","",C23-G23) | Q23: =IF($A23="",0,IF(UPPER(TRIM('가족 목록'!B19))="X",0,1)) | R23: =IF(OR(Q23=0,$Q$4=0),0,CHOOSE($Q$4,1,C23,B23))
A24: =IF('가족 목록'!A20="","",'가족 목록'!A20) | B24: =IF($A24="","",COUNTIFS('부의금 입력'!$A$2:$A$1001,$A24,'부의금 입력'!$G$2:$G$1001,">0")) | C24: =IF($A24="","",SUMIFS('부의금 입력'!$C$2:$C$1001,'부의금 입력'!$A$2:$A$1001,$A24,'부의금 입력'!$G$2:$G$1001,">0")) | D24: =IF($A24="","",IF($B$1=0,0,C24/$B$1)) | E24: =IF($A24="","",COUNTIF('근조 화환'!$A$2:$A$501,$A24)) | G24: =IF(OR($A24="",$Q$4=0),"",IF(SUM($R$6:$R$25)=0,0,지출!$H$4*R24/SUM($R$6:$R$25))) | H24: =IF(G24="","",C24-G24) | Q24: =IF($A24="",0,IF(UPPER(TRIM('가족 목록'!B20))="X",0,1)) | R24: =IF(OR(Q24=0,$Q$4=0),0,CHOOSE($Q$4,1,C24,B24))
A25: =IF('가족 목록'!A21="","",'가족 목록'!A21) | B25: =IF($A25="","",COUNTIFS('부의금 입력'!$A$2:$A$1001,$A25,'부의금 입력'!$G$2:$G$1001,">0")) | C25: =IF($A25="","",SUMIFS('부의금 입력'!$C$2:$C$1001,'부의금 입력'!$A$2:$A$1001,$A25,'부의금 입력'!$G$2:$G$1001,">0")) | D25: =IF($A25="","",IF($B$1=0,0,C25/$B$1)) | E25: =IF($A25="","",COUNTIF('근조 화환'!$A$2:$A$501,$A25)) | G25: =IF(OR($A25="",$Q$4=0),"",IF(SUM($R$6:$R$25)=0,0,지출!$H$4*R25/SUM($R$6:$R$25))) | H25: =IF(G25="","",C25-G25) | Q25: =IF($A25="",0,IF(UPPER(TRIM('가족 목록'!B21))="X",0,1)) | R25: =IF(OR(Q25=0,$Q$4=0),0,CHOOSE($Q$4,1,C25,B25))
A26: 합계 | B26: =SUM(B6:B25) | C26: =SUM(C6:C25) | D26: =SUM(D6:D25) | E26: =SUM(E6:E25) | G26: =SUM(G6:G25) | H26: =SUM(H6:H25) | I26: =SUM(I6:I25)
A27: 가족 목록에 없는 기록 | C27: =B1-C26
A29: 정산 방법 (표 위 노란 칸에서 고르세요)
A30: 1. 똑같이 나누기: 지출 총액 ÷ 참여 가족 수
A31: 장점: 가장 단순하고 설명하기 쉽습니다. 단점: 손님이 적게 온 가족도 똑같이 내서 부담이 클 수 있습니다.
A32: 2. 받은 부의금 비율: 지출 총액 × (내 부의금 ÷ 참여 가족 부의금 합)
A33: 장점: 모두 같은 비율만큼 남아 가장 무난합니다. 단점: 부의금을 많이 받은 가족이 비용도 많이 냅니다.
A34: 3. 손님 수 비율: 지출 총액 × (내 손님 수 ÷ 참여 가족 손님 수 합)
A35: 장점: 식대처럼 손님 수만큼 드는 비용을 반영합니다. 단점: 봉투 하나에 여럿이 와도 1명으로 세고, 금액 차이는 반영하지 않습니다.
A36: 남는 몫 = 받은 부의금 − 지출 분담. 마이너스면 그만큼 더 내야 한다는 뜻입니다.
A37: 비용을 나눠 내지 않을 가족은 '가족 목록' 탭 '정산 참여'에 X. 다르게 정하셨다면 '실제 지급' 칸에 적으세요.

Sheet 가족별
A1: 받은 가족 | B1: ='가족 목록'!A2 | C1: 합계 | D1: =SUMIFS('부의금 입력'!$C$2:$C$1001,'부의금 입력'!$A$2:$A$1001,$B$1,'부의금 입력'!$G$2:$G$1001,">0") | E1: 건수 | F1: =COUNTIFS('부의금 입력'!$A$2:$A$1001,$B$1,'부의금 입력'!$G$2:$G$1001,">0") | H1: 조화·물품 | I1: =COUNTIF('근조 화환'!$A$2:$A$501,$B$1)
A2: ▲ 노란 칸에서 이름을 고르면 그분 명단이 나옵니다.
A3: 번호 | B3: 이름 | C3: 금액 | D3: 소속·관계 | E3: 메모 | H3: 보낸 분 | I3: 종류 | J3: 소속·관계 | K3: 메모
A4: =IF(1<=$F$1,1,"") | B4: =IF($A4="","",INDEX('부의금 입력'!$B$2:$B$1001,MATCH($A4,'부의금 입력'!$H$2:$H$1001,0))&"") | C4: =IF($A4="","",INDEX('부의금 입력'!$C$2:$C$1001,MATCH($A4,'부의금 입력'!$H$2:$H$1001,0))) | D4: =IF($A4="","",INDEX('부의금 입력'!$D$2:$D$1001,MATCH($A4,'부의금 입력'!$H$2:$H$1001,0))&"") | E4: =IF($A4="","",INDEX('부의금 입력'!$E$2:$E$1001,MATCH($A4,'부의금 입력'!$H$2:$H$1001,0))&"") | H4: =IF(1>$I$1,"",INDEX('근조 화환'!$B$2:$B$501,MATCH(1,'근조 화환'!$G$2:$G$501,0))&"") | I4: =IF(1>$I$1,"",INDEX('근조 화환'!$C$2:$C$501,MATCH(1,'근조 화환'!$G$2:$G$501,0))&"") | J4: =IF(1>$I$1,"",INDEX('근조 화환'!$D$2:$D$501,MATCH(1,'근조 화환'!$G$2:$G$501,0))&"") | K4: =IF(1>$I$1,"",INDEX('근조 화환'!$E$2:$E$501,MATCH(1,'근조 화환'!$G$2:$G$501,0))&"")
A5: =IF(2<=$F$1,2,"") | B5: =IF($A5="","",INDEX('부의금 입력'!$B$2:$B$1001,MATCH($A5,'부의금 입력'!$H$2:$H$1001,0))&"") | C5: =IF($A5="","",INDEX('부의금 입력'!$C$2:$C$1001,MATCH($A5,'부의금 입력'!$H$2:$H$1001,0))) | D5: =IF($A5="","",INDEX('부의금 입력'!$D$2:$D$1001,MATCH($A5,'부의금 입력'!$H$2:$H$1001,0))&"") | E5: =IF($A5="","",INDEX('부의금 입력'!$E$2:$E$1001,MATCH($A5,'부의금 입력'!$H$2:$H$1001,0))&"") | H5: =IF(2>$I$1,"",INDEX('근조 화환'!$B$2:$B$501,MATCH(2,'근조 화환'!$G$2:$G$501,0))&"") | I5: =IF(2>$I$1,"",INDEX('근조 화환'!$C$2:$C$501,MATCH(2,'근조 화환'!$G$2:$G$501,0))&"") | J5: =IF(2>$I$1,"",INDEX('근조 화환'!$D$2:$D$501,MATCH(2,'근조 화환'!$G$2:$G$501,0))&"") | K5: =IF(2>$I$1,"",INDEX('근조 화환'!$E$2:$E$501,MATCH(2,'근조 화환'!$G$2:$G$501,0))&"")
A6: =IF(3<=$F$1,3,"") | B6: =IF($A6="","",INDEX('부의금 입력'!$B$2:$B$1001,MATCH($A6,'부의금 입력'!$H$2:$H$1001,0))&"") | C6: =IF($A6="","",INDEX('부의금 입력'!$C$2:$C$1001,MATCH($A6,'부의금 입력'!$H$2:$H$1001,0))) | D6: =IF($A6="","",INDEX('부의금 입력'!$D$2:$D$1001,MATCH($A6,'부의금 입력'!$H$2:$H$1001,0))&"") | E6: =IF($A6="","",INDEX('부의금 입력'!$E$2:$E$1001,MATCH($A6,'부의금 입력'!$H$2:$H$1001,0))&"") | H6: =IF(3>$I$1,"",INDEX('근조 화환'!$B$2:$B$501,MATCH(3,'근조 화환'!$G$2:$G$501,0))&"") | I6: =IF(3>$I$1,"",INDEX('근조 화환'!$C$2:$C$501,MATCH(3,'근조 화환'!$G$2:$G$501,0))&"") | J6: =IF(3>$I$1,"",INDEX('근조 화환'!$D$2:$D$501,MATCH(3,'근조 화환'!$G$2:$G$501,0))&"") | K6: =IF(3>$I$1,"",INDEX('근조 화환'!$E$2:$E$501,MATCH(3,'근조 화환'!$G$2:$G$501,0))&"")
A7: =IF(4<=$F$1,4,"") | B7: =IF($A7="","",INDEX('부의금 입력'!$B$2:$B$1001,MATCH($A7,'부의금 입력'!$H$2:$H$1001,0))&"") | C7: =IF($A7="","",INDEX('부의금 입력'!$C$2:$C$1001,MATCH($A7,'부의금 입력'!$H$2:$H$1001,0))) | D7: =IF($A7="","",INDEX('부의금 입력'!$D$2:$D$1001,MATCH($A7,'부의금 입력'!$H$2:$H$1001,0))&"") | E7: =IF($A7="","",INDEX('부의금 입력'!$E$2:$E$1001,MATCH($A7,'부의금 입력'!$H$2:$H$1001,0))&"") | H7: =IF(4>$I$1,"",INDEX('근조 화환'!$B$2:$B$501,MATCH(4,'근조 화환'!$G$2:$G$501,0))&"") | I7: =IF(4>$I$1,"",INDEX('근조 화환'!$C$2:$C$501,MATCH(4,'근조 화환'!$G$2:$G$501,0))&"") | J7: =IF(4>$I$1,"",INDEX('근조 화환'!$D$2:$D$501,MATCH(4,'근조 화환'!$G$2:$G$501,0))&"") | K7: =IF(4>$I$1,"",INDEX('근조 화환'!$E$2:$E$501,MATCH(4,'근조 화환'!$G$2:$G$501,0))&"")
A8: =IF(5<=$F$1,5,"") | B8: =IF($A8="","",INDEX('부의금 입력'!$B$2:$B$1001,MATCH($A8,'부의금 입력'!$H$2:$H$1001,0))&"") | C8: =IF($A8="","",INDEX('부의금 입력'!$C$2:$C$1001,MATCH($A8,'부의금 입력'!$H$2:$H$1001,0))) | D8: =IF($A8="","",INDEX('부의금 입력'!$D$2:$D$1001,MATCH($A8,'부의금 입력'!$H$2:$H$1001,0))&"") | E8: =IF($A8="","",INDEX('부의금 입력'!$E$2:$E$1001,MATCH($A8,'부의금 입력'!$H$2:$H$1001,0))&"") | H8: =IF(5>$I$1,"",INDEX('근조 화환'!$B$2:$B$501,MATCH(5,'근조 화환'!$G$2:$G$501,0))&"") | I8: =IF(5>$I$1,"",INDEX('근조 화환'!$C$2:$C$501,MATCH(5,'근조 화환'!$G$2:$G$501,0))&"") | J8: =IF(5>$I$1,"",INDEX('근조 화환'!$D$2:$D$501,MATCH(5,'근조 화환'!$G$2:$G$501,0))&"") | K8: =IF(5>$I$1,"",INDEX('근조 화환'!$E$2:$E$501,MATCH(5,'근조 화환'!$G$2:$G$501,0))&"")
A9: =IF(6<=$F$1,6,"") | B9: =IF($A9="","",INDEX('부의금 입력'!$B$2:$B$1001,MATCH($A9,'부의금 입력'!$H$2:$H$1001,0))&"") | C9: =IF($A9="","",INDEX('부의금 입력'!$C$2:$C$1001,MATCH($A9,'부의금 입력'!$H$2:$H$1001,0))) | D9: =IF($A9="","",INDEX('부의금 입력'!$D$2:$D$1001,MATCH($A9,'부의금 입력'!$H$2:$H$1001,0))&"") | E9: =IF($A9="","",INDEX('부의금 입력'!$E$2:$E$1001,MATCH($A9,'부의금 입력'!$H$2:$H$1001,0))&"") | H9: =IF(6>$I$1,"",INDEX('근조 화환'!$B$2:$B$501,MATCH(6,'근조 화환'!$G$2:$G$501,0))&"") | I9: =IF(6>$I$1,"",INDEX('근조 화환'!$C$2:$C$501,MATCH(6,'근조 화환'!$G$2:$G$501,0))&"") | J9: =IF(6>$I$1,"",INDEX('근조 화환'!$D$2:$D$501,MATCH(6,'근조 화환'!$G$2:$G$501,0))&"") | K9: =IF(6>$I$1,"",INDEX('근조 화환'!$E$2:$E$501,MATCH(6,'근조 화환'!$G$2:$G$501,0))&"")
A10: =IF(7<=$F$1,7,"") | B10: =IF($A10="","",INDEX('부의금 입력'!$B$2:$B$1001,MATCH($A10,'부의금 입력'!$H$2:$H$1001,0))&"") | C10: =IF($A10="","",INDEX('부의금 입력'!$C$2:$C$1001,MATCH($A10,'부의금 입력'!$H$2:$H$1001,0))) | D10: =IF($A10="","",INDEX('부의금 입력'!$D$2:$D$1001,MATCH($A10,'부의금 입력'!$H$2:$H$1001,0))&"") | E10: =IF($A10="","",INDEX('부의금 입력'!$E$2:$E$1001,MATCH($A10,'부의금 입력'!$H$2:$H$1001,0))&"") | H10: =IF(7>$I$1,"",INDEX('근조 화환'!$B$2:$B$501,MATCH(7,'근조 화환'!$G$2:$G$501,0))&"") | I10: =IF(7>$I$1,"",INDEX('근조 화환'!$C$2:$C$501,MATCH(7,'근조 화환'!$G$2:$G$501,0))&"") | J10: =IF(7>$I$1,"",INDEX('근조 화환'!$D$2:$D$501,MATCH(7,'근조 화환'!$G$2:$G$501,0))&"") | K10: =IF(7>$I$1,"",INDEX('근조 화환'!$E$2:$E$501,MATCH(7,'근조 화환'!$G$2:$G$501,0))&"")
A11: =IF(8<=$F$1,8,"") | B11: =IF($A11="","",INDEX('부의금 입력'!$B$2:$B$1001,MATCH($A11,'부의금 입력'!$H$2:$H$1001,0))&"") | C11: =IF($A11="","",INDEX('부의금 입력'!$C$2:$C$1001,MATCH($A11,'부의금 입력'!$H$2:$H$1001,0))) | D11: =IF($A11="","",INDEX('부의금 입력'!$D$2:$D$1001,MATCH($A11,'부의금 입력'!$H$2:$H$1001,0))&"") | E11: =IF($A11="","",INDEX('부의금 입력'!$E$2:$E$1001,MATCH($A11,'부의금 입력'!$H$2:$H$1001,0))&"") | H11: =IF(8>$I$1,"",INDEX('근조 화환'!$B$2:$B$501,MATCH(8,'근조 화환'!$G$2:$G$501,0))&"") | I11: =IF(8>$I$1,"",INDEX('근조 화환'!$C$2:$C$501,MATCH(8,'근조 화환'!$G$2:$G$501,0))&"") | J11: =IF(8>$I$1,"",INDEX('근조 화환'!$D$2:$D$501,MATCH(8,'근조 화환'!$G$2:$G$501,0))&"") | K11: =IF(8>$I$1,"",INDEX('근조 화환'!$E$2:$E$501,MATCH(8,'근조 화환'!$G$2:$G$501,0))&"")
A12: =IF(9<=$F$1,9,"") | B12: =IF($A12="","",INDEX('부의금 입력'!$B$2:$B$1001,MATCH($A12,'부의금 입력'!$H$2:$H$1001,0))&"") | C12: =IF($A12="","",INDEX('부의금 입력'!$C$2:$C$1001,MATCH($A12,'부의금 입력'!$H$2:$H$1001,0))) | D12: =IF($A12="","",INDEX('부의금 입력'!$D$2:$D$1001,MATCH($A12,'부의금 입력'!$H$2:$H$1001,0))&"") | E12: =IF($A12="","",INDEX('부의금 입력'!$E$2:$E$1001,MATCH($A12,'부의금 입력'!$H$2:$H$1001,0))&"") | H12: =IF(9>$I$1,"",INDEX('근조 화환'!$B$2:$B$501,MATCH(9,'근조 화환'!$G$2:$G$501,0))&"") | I12: =IF(9>$I$1,"",INDEX('근조 화환'!$C$2:$C$501,MATCH(9,'근조 화환'!$G$2:$G$501,0))&"") | J12: =IF(9>$I$1,"",INDEX('근조 화환'!$D$2:$D$501,MATCH(9,'근조 화환'!$G$2:$G$501,0))&"") | K12: =IF(9>$I$1,"",INDEX('근조 화환'!$E$2:$E$501,MATCH(9,'근조 화환'!$G$2:$G$501,0))&"")
A13: =IF(10<=$F$1,10,"") | B13: =IF($A13="","",INDEX('부의금 입력'!$B$2:$B$1001,MATCH($A13,'부의금 입력'!$H$2:$H$1001,0))&"") | C13: =IF($A13="","",INDEX('부의금 입력'!$C$2:$C$1001,MATCH($A13,'부의금 입력'!$H$2:$H$1001,0))) | D13: =IF($A13="","",INDEX('부의금 입력'!$D$2:$D$1001,MATCH($A13,'부의금 입력'!$H$2:$H$1001,0))&"") | E13: =IF($A13="","",INDEX('부의금 입력'!$E$2:$E$1001,MATCH($A13,'부의금 입력'!$H$2:$H$1001,0))&"") | H13: =IF(10>$I$1,"",INDEX('근조 화환'!$B$2:$B$501,MATCH(10,'근조 화환'!$G$2:$G$501,0))&"") | I13: =IF(10>$I$1,"",INDEX('근조 화환'!$C$2:$C$501,MATCH(10,'근조 화환'!$G$2:$G$501,0))&"") | J13: =IF(10>$I$1,"",INDEX('근조 화환'!$D$2:$D$501,MATCH(10,'근조 화환'!$G$2:$G$501,0))&"") | K13: =IF(10>$I$1,"",INDEX('근조 화환'!$E$2:$E$501,MATCH(10,'근조 화환'!$G$2:$G$501,0))&"")
A14: =IF(11<=$F$1,11,"") | B14: =IF($A14="","",INDEX('부의금 입력'!$B$2:$B$1001,MATCH($A14,'부의금 입력'!$H$2:$H$1001,0))&"") | C14: =IF($A14="","",INDEX('부의금 입력'!$C$2:$C$1001,MATCH($A14,'부의금 입력'!$H$2:$H$1001,0))) | D14: =IF($A14="","",INDEX('부의금 입력'!$D$2:$D$1001,MATCH($A14,'부의금 입력'!$H$2:$H$1001,0))&"") | E14: =IF($A14="","",INDEX('부의금 입력'!$E$2:$E$1001,MATCH($A14,'부의금 입력'!$H$2:$H$1001,0))&"") | H14: =IF(11>$I$1,"",INDEX('근조 화환'!$B$2:$B$501,MATCH(11,'근조 화환'!$G$2:$G$501,0))&"") | I14: =IF(11>$I$1,"",INDEX('근조 화환'!$C$2:$C$501,MATCH(11,'근조 화환'!$G$2:$G$501,0))&"") | J14: =IF(11>$I$1,"",INDEX('근조 화환'!$D$2:$D$501,MATCH(11,'근조 화환'!$G$2:$G$501,0))&"") | K14: =IF(11>$I$1,"",INDEX('근조 화환'!$E$2:$E$501,MATCH(11,'근조 화환'!$G$2:$G$501,0))&"")
A15: =IF(12<=$F$1,12,"") | B15: =IF($A15="","",INDEX('부의금 입력'!$B$2:$B$1001,MATCH($A15,'부의금 입력'!$H$2:$H$1001,0))&"") | C15: =IF($A15="","",INDEX('부의금 입력'!$C$2:$C$1001,MATCH($A15,'부의금 입력'!$H$2:$H$1001,0))) | D15: =IF($A15="","",INDEX('부의금 입력'!$D$2:$D$1001,MATCH($A15,'부의금 입력'!$H$2:$H$1001,0))&"") | E15: =IF($A15="","",INDEX('부의금 입력'!$E$2:$E$1001,MATCH($A15,'부의금 입력'!$H$2:$H$1001,0))&"") | H15: =IF(12>$I$1,"",INDEX('근조 화환'!$B$2:$B$501,MATCH(12,'근조 화환'!$G$2:$G$501,0))&"") | I15: =IF(12>$I$1,"",INDEX('근조 화환'!$C$2:$C$501,MATCH(12,'근조 화환'!$G$2:$G$501,0))&"") | J15: =IF(12>$I$1,"",INDEX('근조 화환'!$D$2:$D$501,MATCH(12,'근조 화환'!$G$2:$G$501,0))&"") | K15: =IF(12>$I$1,"",INDEX('근조 화환'!$E$2:$E$501,MATCH(12,'근조 화환'!$G$2:$G$501,0))&"")
A16: =IF(13<=$F$1,13,"") | B16: =IF($A16="","",INDEX('부의금 입력'!$B$2:$B$1001,MATCH($A16,'부의금 입력'!$H$2:$H$1001,0))&"") | C16: =IF($A16="","",INDEX('부의금 입력'!$C$2:$C$1001,MATCH($A16,'부의금 입력'!$H$2:$H$1001,0))) | D16: =IF($A16="","",INDEX('부의금 입력'!$D$2:$D$1001,MATCH($A16,'부의금 입력'!$H$2:$H$1001,0))&"") | E16: =IF($A16="","",INDEX('부의금 입력'!$E$2:$E$1001,MATCH($A16,'부의금 입력'!$H$2:$H$1001,0))&"") | H16: =IF(13>$I$1,"",INDEX('근조 화환'!$B$2:$B$501,MATCH(13,'근조 화환'!$G$2:$G$501,0))&"") | I16: =IF(13>$I$1,"",INDEX('근조 화환'!$C$2:$C$501,MATCH(13,'근조 화환'!$G$2:$G$501,0))&"") | J16: =IF(13>$I$1,"",INDEX('근조 화환'!$D$2:$D$501,MATCH(13,'근조 화환'!$G$2:$G$501,0))&"") | K16: =IF(13>$I$1,"",INDEX('근조 화환'!$E$2:$E$501,MATCH(13,'근조 화환'!$G$2:$G$501,0))&"")
A17: =IF(14<=$F$1,14,"") | B17: =IF($A17="","",INDEX('부의금 입력'!$B$2:$B$1001,MATCH($A17,'부의금 입력'!$H$2:$H$1001,0))&"") | C17: =IF($A17="","",INDEX('부의금 입력'!$C$2:$C$1001,MATCH($A17,'부의금 입력'!$H$2:$H$1001,0))) | D17: =IF($A17="","",INDEX('부의금 입력'!$D$2:$D$1001,MATCH($A17,'부의금 입력'!$H$2:$H$1001,0))&"") | E17: =IF($A17="","",INDEX('부의금 입력'!$E$2:$E$1001,MATCH($A17,'부의금 입력'!$H$2:$H$1001,0))&"") | H17: =IF(14>$I$1,"",INDEX('근조 화환'!$B$2:$B$501,MATCH(14,'근조 화환'!$G$2:$G$501,0))&"") | I17: =IF(14>$I$1,"",INDEX('근조 화환'!$C$2:$C$501,MATCH(14,'근조 화환'!$G$2:$G$501,0))&"") | J17: =IF(14>$I$1,"",INDEX('근조 화환'!$D$2:$D$501,MATCH(14,'근조 화환'!$G$2:$G$501,0))&"") | K17: =IF(14>$I$1,"",INDEX('근조 화환'!$E$2:$E$501,MATCH(14,'근조 화환'!$G$2:$G$501,0))&"")
A18: =IF(15<=$F$1,15,"") | B18: =IF($A18="","",INDEX('부의금 입력'!$B$2:$B$1001,MATCH($A18,'부의금 입력'!$H$2:$H$1001,0))&"") | C18: =IF($A18="","",INDEX('부의금 입력'!$C$2:$C$1001,MATCH($A18,'부의금 입력'!$H$2:$H$1001,0))) | D18: =IF($A18="","",INDEX('부의금 입력'!$D$2:$D$1001,MATCH($A18,'부의금 입력'!$H$2:$H$1001,0))&"") | E18: =IF($A18="","",INDEX('부의금 입력'!$E$2:$E$1001,MATCH($A18,'부의금 입력'!$H$2:$H$1001,0))&"") | H18: =IF(15>$I$1,"",INDEX('근조 화환'!$B$2:$B$501,MATCH(15,'근조 화환'!$G$2:$G$501,0))&"") | I18: =IF(15>$I$1,"",INDEX('근조 화환'!$C$2:$C$501,MATCH(15,'근조 화환'!$G$2:$G$501,0))&"") | J18: =IF(15>$I$1,"",INDEX('근조 화환'!$D$2:$D$501,MATCH(15,'근조 화환'!$G$2:$G$501,0))&"") | K18: =IF(15>$I$1,"",INDEX('근조 화환'!$E$2:$E$501,MATCH(15,'근조 화환'!$G$2:$G$501,0))&"")
A19: =IF(16<=$F$1,16,"") | B19: =IF($A19="","",INDEX('부의금 입력'!$B$2:$B$1001,MATCH($A19,'부의금 입력'!$H$2:$H$1001,0))&"") | C19: =IF($A19="","",INDEX('부의금 입력'!$C$2:$C$1001,MATCH($A19,'부의금 입력'!$H$2:$H$1001,0))) | D19: =IF($A19="","",INDEX('부의금 입력'!$D$2:$D$1001,MATCH($A19,'부의금 입력'!$H$2:$H$1001,0))&"") | E19: =IF($A19="","",INDEX('부의금 입력'!$E$2:$E$1001,MATCH($A19,'부의금 입력'!$H$2:$H$1001,0))&"") | H19: =IF(16>$I$1,"",INDEX('근조 화환'!$B$2:$B$501,MATCH(16,'근조 화환'!$G$2:$G$501,0))&"") | I19: =IF(16>$I$1,"",INDEX('근조 화환'!$C$2:$C$501,MATCH(16,'근조 화환'!$G$2:$G$501,0))&"") | J19: =IF(16>$I$1,"",INDEX('근조 화환'!$D$2:$D$501,MATCH(16,'근조 화환'!$G$2:$G$501,0))&"") | K19: =IF(16>$I$1,"",INDEX('근조 화환'!$E$2:$E$501,MATCH(16,'근조 화환'!$G$2:$G$501,0))&"")
A20: =IF(17<=$F$1,17,"") | B20: =IF($A20="","",INDEX('부의금 입력'!$B$2:$B$1001,MATCH($A20,'부의금 입력'!$H$2:$H$1001,0))&"") | C20: =IF($A20="","",INDEX('부의금 입력'!$C$2:$C$1001,MATCH($A20,'부의금 입력'!$H$2:$H$1001,0))) | D20: =IF($A20="","",INDEX('부의금 입력'!$D$2:$D$1001,MATCH($A20,'부의금 입력'!$H$2:$H$1001,0))&"") | E20: =IF($A20="","",INDEX('부의금 입력'!$E$2:$E$1001,MATCH($A20,'부의금 입력'!$H$2:$H$1001,0))&"") | H20: =IF(17>$I$1,"",INDEX('근조 화환'!$B$2:$B$501,MATCH(17,'근조 화환'!$G$2:$G$501,0))&"") | I20: =IF(17>$I$1,"",INDEX('근조 화환'!$C$2:$C$501,MATCH(17,'근조 화환'!$G$2:$G$501,0))&"") | J20: =IF(17>$I$1,"",INDEX('근조 화환'!$D$2:$D$501,MATCH(17,'근조 화환'!$G$2:$G$501,0))&"") | K20: =IF(17>$I$1,"",INDEX('근조 화환'!$E$2:$E$501,MATCH(17,'근조 화환'!$G$2:$G$501,0))&"")
A21: =IF(18<=$F$1,18,"") | B21: =IF($A21="","",INDEX('부의금 입력'!$B$2:$B$1001,MATCH($A21,'부의금 입력'!$H$2:$H$1001,0))&"") | C21: =IF($A21="","",INDEX('부의금 입력'!$C$2:$C$1001,MATCH($A21,'부의금 입력'!$H$2:$H$1001,0))) | D21: =IF($A21="","",INDEX('부의금 입력'!$D$2:$D$1001,MATCH($A21,'부의금 입력'!$H$2:$H$1001,0))&"") | E21: =IF($A21="","",INDEX('부의금 입력'!$E$2:$E$1001,MATCH($A21,'부의금 입력'!$H$2:$H$1001,0))&"") | H21: =IF(18>$I$1,"",INDEX('근조 화환'!$B$2:$B$501,MATCH(18,'근조 화환'!$G$2:$G$501,0))&"") | I21: =IF(18>$I$1,"",INDEX('근조 화환'!$C$2:$C$501,MATCH(18,'근조 화환'!$G$2:$G$501,0))&"") | J21: =IF(18>$I$1,"",INDEX('근조 화환'!$D$2:$D$501,MATCH(18,'근조 화환'!$G$2:$G$501,0))&"") | K21: =IF(18>$I$1,"",INDEX('근조 화환'!$E$2:$E$501,MATCH(18,'근조 화환'!$G$2:$G$501,0))&"")
A22: =IF(19<=$F$1,19,"") | B22: =IF($A22="","",INDEX('부의금 입력'!$B$2:$B$1001,MATCH($A22,'부의금 입력'!$H$2:$H$1001,0))&"") | C22: =IF($A22="","",INDEX('부의금 입력'!$C$2:$C$1001,MATCH($A22,'부의금 입력'!$H$2:$H$1001,0))) | D22: =IF($A22="","",INDEX('부의금 입력'!$D$2:$D$1001,MATCH($A22,'부의금 입력'!$H$2:$H$1001,0))&"") | E22: =IF($A22="","",INDEX('부의금 입력'!$E$2:$E$1001,MATCH($A22,'부의금 입력'!$H$2:$H$1001,0))&"") | H22: =IF(19>$I$1,"",INDEX('근조 화환'!$B$2:$B$501,MATCH(19,'근조 화환'!$G$2:$G$501,0))&"") | I22: =IF(19>$I$1,"",INDEX('근조 화환'!$C$2:$C$501,MATCH(19,'근조 화환'!$G$2:$G$501,0))&"") | J22: =IF(19>$I$1,"",INDEX('근조 화환'!$D$2:$D$501,MATCH(19,'근조 화환'!$G$2:$G$501,0))&"") | K22: =IF(19>$I$1,"",INDEX('근조 화환'!$E$2:$E$501,MATCH(19,'근조 화환'!$G$2:$G$501,0))&"")
A23: =IF(20<=$F$1,20,"") | B23: =IF($A23="","",INDEX('부의금 입력'!$B$2:$B$1001,MATCH($A23,'부의금 입력'!$H$2:$H$1001,0))&"") | C23: =IF($A23="","",INDEX('부의금 입력'!$C$2:$C$1001,MATCH($A23,'부의금 입력'!$H$2:$H$1001,0))) | D23: =IF($A23="","",INDEX('부의금 입력'!$D$2:$D$1001,MATCH($A23,'부의금 입력'!$H$2:$H$1001,0))&"") | E23: =IF($A23="","",INDEX('부의금 입력'!$E$2:$E$1001,MATCH($A23,'부의금 입력'!$H$2:$H$1001,0))&"") | H23: =IF(20>$I$1,"",INDEX('근조 화환'!$B$2:$B$501,MATCH(20,'근조 화환'!$G$2:$G$501,0))&"") | I23: =IF(20>$I$1,"",INDEX('근조 화환'!$C$2:$C$501,MATCH(20,'근조 화환'!$G$2:$G$501,0))&"") | J23: =IF(20>$I$1,"",INDEX('근조 화환'!$D$2:$D$501,MATCH(20,'근조 화환'!$G$2:$G$501,0))&"") | K23: =IF(20>$I$1,"",INDEX('근조 화환'!$E$2:$E$501,MATCH(20,'근조 화환'!$G$2:$G$501,0))&"")
A24: =IF(21<=$F$1,21,"") | B24: =IF($A24="","",INDEX('부의금 입력'!$B$2:$B$1001,MATCH($A24,'부의금 입력'!$H$2:$H$1001,0))&"") | C24: =IF($A24="","",INDEX('부의금 입력'!$C$2:$C$1001,MATCH($A24,'부의금 입력'!$H$2:$H$1001,0))) | D24: =IF($A24="","",INDEX('부의금 입력'!$D$2:$D$1001,MATCH($A24,'부의금 입력'!$H$2:$H$1001,0))&"") | E24: =IF($A24="","",INDEX('부의금 입력'!$E$2:$E$1001,MATCH($A24,'부의금 입력'!$H$2:$H$1001,0))&"") | H24: =IF(21>$I$1,"",INDEX('근조 화환'!$B$2:$B$501,MATCH(21,'근조 화환'!$G$2:$G$501,0))&"") | I24: =IF(21>$I$1,"",INDEX('근조 화환'!$C$2:$C$501,MATCH(21,'근조 화환'!$G$2:$G$501,0))&"") | J24: =IF(21>$I$1,"",INDEX('근조 화환'!$D$2:$D$501,MATCH(21,'근조 화환'!$G$2:$G$501,0))&"") | K24: =IF(21>$I$1,"",INDEX('근조 화환'!$E$2:$E$501,MATCH(21,'근조 화환'!$G$2:$G$501,0))&"")
A25: =IF(22<=$F$1,22,"") | B25: =IF($A25="","",INDEX('부의금 입력'!$B$2:$B$1001,MATCH($A25,'부의금 입력'!$H$2:$H$1001,0))&"") | C25: =IF($A25="","",INDEX('부의금 입력'!$C$2:$C$1001,MATCH($A25,'부의금 입력'!$H$2:$H$1001,0))) | D25: =IF($A25="","",INDEX('부의금 입력'!$D$2:$D$1001,MATCH($A25,'부의금 입력'!$H$2:$H$1001,0))&"") | E25: =IF($A25="","",INDEX('부의금 입력'!$E$2:$E$1001,MATCH($A25,'부의금 입력'!$H$2:$H$1001,0))&"") | H25: =IF(22>$I$1,"",INDEX('근조 화환'!$B$2:$B$501,MATCH(22,'근조 화환'!$G$2:$G$501,0))&"") | I25: =IF(22>$I$1,"",INDEX('근조 화환'!$C$2:$C$501,MATCH(22,'근조 화환'!$G$2:$G$501,0))&"") | J25: =IF(22>$I$1,"",INDEX('근조 화환'!$D$2:$D$501,MATCH(22,'근조 화환'!$G$2:$G$501,0))&"") | K25: =IF(22>$I$1,"",INDEX('근조 화환'!$E$2:$E$501,MATCH(22,'근조 화환'!$G$2:$G$501,0))&"")
A26: =IF(23<=$F$1,23,"") | B26: =IF($A26="","",INDEX('부의금 입력'!$B$2:$B$1001,MATCH($A26,'부의금 입력'!$H$2:$H$1001,0))&"") | C26: =IF($A26="","",INDEX('부의금 입력'!$C$2:$C$1001,MATCH($A26,'부의금 입력'!$H$2:$H$1001,0))) | D26: =IF($A26="","",INDEX('부의금 입력'!$D$2:$D$1001,MATCH($A26,'부의금 입력'!$H$2:$H$1001,0))&"") | E26: =IF($A26="","",INDEX('부의금 입력'!$E$2:$E$1001,MATCH($A26,'부의금 입력'!$H$2:$H$1001,0))&"") | H26: =IF(23>$I$1,"",INDEX('근조 화환'!$B$2:$B$501,MATCH(23,'근조 화환'!$G$2:$G$501,0))&"") | I26: =IF(23>$I$1,"",INDEX('근조 화환'!$C$2:$C$501,MATCH(23,'근조 화환'!$G$2:$G$501,0))&"") | J26: =IF(23>$I$1,"",INDEX('근조 화환'!$D$2:$D$501,MATCH(23,'근조 화환'!$G$2:$G$501,0))&"") | K26: =IF(23>$I$1,"",INDEX('근조 화환'!$E$2:$E$501,MATCH(23,'근조 화환'!$G$2:$G$501,0))&"")
A27: =IF(24<=$F$1,24,"") | B27: =IF($A27="","",INDEX('부의금 입력'!$B$2:$B$1001,MATCH($A27,'부의금 입력'!$H$2:$H$1001,0))&"") | C27: =IF($A27="","",INDEX('부의금 입력'!$C$2:$C$1001,MATCH($A27,'부의금 입력'!$H$2:$H$1001,0))) | D27: =IF($A27="","",INDEX('부의금 입력'!$D$2:$D$1001,MATCH($A27,'부의금 입력'!$H$2:$H$1001,0))&"") | E27: =IF($A27="","",INDEX('부의금 입력'!$E$2:$E$1001,MATCH($A27,'부의금 입력'!$H$2:$H$1001,0))&"") | H27: =IF(24>$I$1,"",INDEX('근조 화환'!$B$2:$B$501,MATCH(24,'근조 화환'!$G$2:$G$501,0))&"") | I27: =IF(24>$I$1,"",INDEX('근조 화환'!$C$2:$C$501,MATCH(24,'근조 화환'!$G$2:$G$501,0))&"") | J27: =IF(24>$I$1,"",INDEX('근조 화환'!$D$2:$D$501,MATCH(24,'근조 화환'!$G$2:$G$501,0))&"") | K27: =IF(24>$I$1,"",INDEX('근조 화환'!$E$2:$E$501,MATCH(24,'근조 화환'!$G$2:$G$501,0))&"")
A28: =IF(25<=$F$1,25,"") | B28: =IF($A28="","",INDEX('부의금 입력'!$B$2:$B$1001,MATCH($A28,'부의금 입력'!$H$2:$H$1001,0))&"") | C28: =IF($A28="","",INDEX('부의금 입력'!$C$2:$C$1001,MATCH($A28,'부의금 입력'!$H$2:$H$1001,0))) | D28: =IF($A28="","",INDEX('부의금 입력'!$D$2:$D$1001,MATCH($A28,'부의금 입력'!$H$2:$H$1001,0))&"") | E28: =IF($A28="","",INDEX('부의금 입력'!$E$2:$E$1001,MATCH($A28,'부의금 입력'!$H$2:$H$1001,0))&"") | H28: =IF(25>$I$1,"",INDEX('근조 화환'!$B$2:$B$501,MATCH(25,'근조 화환'!$G$2:$G$501,0))&"") | I28: =IF(25>$I$1,"",INDEX('근조 화환'!$C$2:$C$501,MATCH(25,'근조 화환'!$G$2:$G$501,0))&"") | J28: =IF(25>$I$1,"",INDEX('근조 화환'!$D$2:$D$501,MATCH(25,'근조 화환'!$G$2:$G$501,0))&"") | K28: =IF(25>$I$1,"",INDEX('근조 화환'!$E$2:$E$501,MATCH(25,'근조 화환'!$G$2:$G$501,0))&"")
A29: =IF(26<=$F$1,26,"") | B29: =IF($A29="","",INDEX('부의금 입력'!$B$2:$B$1001,MATCH($A29,'부의금 입력'!$H$2:$H$1001,0))&"") | C29: =IF($A29="","",INDEX('부의금 입력'!$C$2:$C$1001,MATCH($A29,'부의금 입력'!$H$2:$H$1001,0))) | D29: =IF($A29="","",INDEX('부의금 입력'!$D$2:$D$1001,MATCH($A29,'부의금 입력'!$H$2:$H$1001,0))&"") | E29: =IF($A29="","",INDEX('부의금 입력'!$E$2:$E$1001,MATCH($A29,'부의금 입력'!$H$2:$H$1001,0))&"") | H29: =IF(26>$I$1,"",INDEX('근조 화환'!$B$2:$B$501,MATCH(26,'근조 화환'!$G$2:$G$501,0))&"") | I29: =IF(26>$I$1,"",INDEX('근조 화환'!$C$2:$C$501,MATCH(26,'근조 화환'!$G$2:$G$501,0))&"") | J29: =IF(26>$I$1,"",INDEX('근조 화환'!$D$2:$D$501,MATCH(26,'근조 화환'!$G$2:$G$501,0))&"") | K29: =IF(26>$I$1,"",INDEX('근조 화환'!$E$2:$E$501,MATCH(26,'근조 화환'!$G$2:$G$501,0))&"")
A30: =IF(27<=$F$1,27,"") | B30: =IF($A30="","",INDEX('부의금 입력'!$B$2:$B$1001,MATCH($A30,'부의금 입력'!$H$2:$H$1001,0))&"") | C30: =IF($A30="","",INDEX('부의금 입력'!$C$2:$C$1001,MATCH($A30,'부의금 입력'!$H$2:$H$1001,0))) | D30: =IF($A30="","",INDEX('부의금 입력'!$D$2:$D$1001,MATCH($A30,'부의금 입력'!$H$2:$H$1001,0))&"") | E30: =IF($A30="","",INDEX('부의금 입력'!$E$2:$E$1001,MATCH($A30,'부의금 입력'!$H$2:$H$1001,0))&"") | H30: =IF(27>$I$1,"",INDEX('근조 화환'!$B$2:$B$501,MATCH(27,'근조 화환'!$G$2:$G$501,0))&"") | I30: =IF(27>$I$1,"",INDEX('근조 화환'!$C$2:$C$501,MATCH(27,'근조 화환'!$G$2:$G$501,0))&"") | J30: =IF(27>$I$1,"",INDEX('근조 화환'!$D$2:$D$501,MATCH(27,'근조 화환'!$G$2:$G$501,0))&"") | K30: =IF(27>$I$1,"",INDEX('근조 화환'!$E$2:$E$501,MATCH(27,'근조 화환'!$G$2:$G$501,0))&"")
A31: =IF(28<=$F$1,28,"") | B31: =IF($A31="","",INDEX('부의금 입력'!$B$2:$B$1001,MATCH($A31,'부의금 입력'!$H$2:$H$1001,0))&"") | C31: =IF($A31="","",INDEX('부의금 입력'!$C$2:$C$1001,MATCH($A31,'부의금 입력'!$H$2:$H$1001,0))) | D31: =IF($A31="","",INDEX('부의금 입력'!$D$2:$D$1001,MATCH($A31,'부의금 입력'!$H$2:$H$1001,0))&"") | E31: =IF($A31="","",INDEX('부의금 입력'!$E$2:$E$1001,MATCH($A31,'부의금 입력'!$H$2:$H$1001,0))&"") | H31: =IF(28>$I$1,"",INDEX('근조 화환'!$B$2:$B$501,MATCH(28,'근조 화환'!$G$2:$G$501,0))&"") | I31: =IF(28>$I$1,"",INDEX('근조 화환'!$C$2:$C$501,MATCH(28,'근조 화환'!$G$2:$G$501,0))&"") | J31: =IF(28>$I$1,"",INDEX('근조 화환'!$D$2:$D$501,MATCH(28,'근조 화환'!$G$2:$G$501,0))&"") | K31: =IF(28>$I$1,"",INDEX('근조 화환'!$E$2:$E$501,MATCH(28,'근조 화환'!$G$2:$G$501,0))&"")
A32: =IF(29<=$F$1,29,"") | B32: =IF($A32="","",INDEX('부의금 입력'!$B$2:$B$1001,MATCH($A32,'부의금 입력'!$H$2:$H$1001,0))&"") | C32: =IF($A32="","",INDEX('부의금 입력'!$C$2:$C$1001,MATCH($A32,'부의금 입력'!$H$2:$H$1001,0))) | D32: =IF($A32="","",INDEX('부의금 입력'!$D$2:$D$1001,MATCH($A32,'부의금 입력'!$H$2:$H$1001,0))&"") | E32: =IF($A32="","",INDEX('부의금 입력'!$E$2:$E$1001,MATCH($A32,'부의금 입력'!$H$2:$H$1001,0))&"") | H32: =IF(29>$I$1,"",INDEX('근조 화환'!$B$2:$B$501,MATCH(29,'근조 화환'!$G$2:$G$501,0))&"") | I32: =IF(29>$I$1,"",INDEX('근조 화환'!$C$2:$C$501,MATCH(29,'근조 화환'!$G$2:$G$501,0))&"") | J32: =IF(29>$I$1,"",INDEX('근조 화환'!$D$2:$D$501,MATCH(29,'근조 화환'!$G$2:$G$501,0))&"") | K32: =IF(29>$I$1,"",INDEX('근조 화환'!$E$2:$E$501,MATCH(29,'근조 화환'!$G$2:$G$501,0))&"")
A33: =IF(30<=$F$1,30,"") | B33: =IF($A33="","",INDEX('부의금 입력'!$B$2:$B$1001,MATCH($A33,'부의금 입력'!$H$2:$H$1001,0))&"") | C33: =IF($A33="","",INDEX('부의금 입력'!$C$2:$C$1001,MATCH($A33,'부의금 입력'!$H$2:$H$1001,0))) | D33: =IF($A33="","",INDEX('부의금 입력'!$D$2:$D$1001,MATCH($A33,'부의금 입력'!$H$2:$H$1001,0))&"") | E33: =IF($A33="","",INDEX('부의금 입력'!$E$2:$E$1001,MATCH($A33,'부의금 입력'!$H$2:$H$1001,0))&"") | H33: =IF(30>$I$1,"",INDEX('근조 화환'!$B$2:$B$501,MATCH(30,'근조 화환'!$G$2:$G$501,0))&"") | I33: =IF(30>$I$1,"",INDEX('근조 화환'!$C$2:$C$501,MATCH(30,'근조 화환'!$G$2:$G$501,0))&"") | J33: =IF(30>$I$1,"",INDEX('근조 화환'!$D$2:$D$501,MATCH(30,'근조 화환'!$G$2:$G$501,0))&"") | K33: =IF(30>$I$1,"",INDEX('근조 화환'!$E$2:$E$501,MATCH(30,'근조 화환'!$G$2:$G$501,0))&"")
A34: =IF(31<=$F$1,31,"") | B34: =IF($A34="","",INDEX('부의금 입력'!$B$2:$B$1001,MATCH($A34,'부의금 입력'!$H$2:$H$1001,0))&"") | C34: =IF($A34="","",INDEX('부의금 입력'!$C$2:$C$1001,MATCH($A34,'부의금 입력'!$H$2:$H$1001,0))) | D34: =IF($A34="","",INDEX('부의금 입력'!$D$2:$D$1001,MATCH($A34,'부의금 입력'!$H$2:$H$1001,0))&"") | E34: =IF($A34="","",INDEX('부의금 입력'!$E$2:$E$1001,MATCH($A34,'부의금 입력'!$H$2:$H$1001,0))&"") | H34: =IF(31>$I$1,"",INDEX('근조 화환'!$B$2:$B$501,MATCH(31,'근조 화환'!$G$2:$G$501,0))&"") | I34: =IF(31>$I$1,"",INDEX('근조 화환'!$C$2:$C$501,MATCH(31,'근조 화환'!$G$2:$G$501,0))&"") | J34: =IF(31>$I$1,"",INDEX('근조 화환'!$D$2:$D$501,MATCH(31,'근조 화환'!$G$2:$G$501,0))&"") | K34: =IF(31>$I$1,"",INDEX('근조 화환'!$E$2:$E$501,MATCH(31,'근조 화환'!$G$2:$G$501,0))&"")
A35: =IF(32<=$F$1,32,"") | B35: =IF($A35="","",INDEX('부의금 입력'!$B$2:$B$1001,MATCH($A35,'부의금 입력'!$H$2:$H$1001,0))&"") | C35: =IF($A35="","",INDEX('부의금 입력'!$C$2:$C$1001,MATCH($A35,'부의금 입력'!$H$2:$H$1001,0))) | D35: =IF($A35="","",INDEX('부의금 입력'!$D$2:$D$1001,MATCH($A35,'부의금 입력'!$H$2:$H$1001,0))&"") | E35: =IF($A35="","",INDEX('부의금 입력'!$E$2:$E$1001,MATCH($A35,'부의금 입력'!$H$2:$H$1001,0))&"") | H35: =IF(32>$I$1,"",INDEX('근조 화환'!$B$2:$B$501,MATCH(32,'근조 화환'!$G$2:$G$501,0))&"") | I35: =IF(32>$I$1,"",INDEX('근조 화환'!$C$2:$C$501,MATCH(32,'근조 화환'!$G$2:$G$501,0))&"") | J35: =IF(32>$I$1,"",INDEX('근조 화환'!$D$2:$D$501,MATCH(32,'근조 화환'!$G$2:$G$501,0))&"") | K35: =IF(32>$I$1,"",INDEX('근조 화환'!$E$2:$E$501,MATCH(32,'근조 화환'!$G$2:$G$501,0))&"")
A36: =IF(33<=$F$1,33,"") | B36: =IF($A36="","",INDEX('부의금 입력'!$B$2:$B$1001,MATCH($A36,'부의금 입력'!$H$2:$H$1001,0))&"") | C36: =IF($A36="","",INDEX('부의금 입력'!$C$2:$C$1001,MATCH($A36,'부의금 입력'!$H$2:$H$1001,0))) | D36: =IF($A36="","",INDEX('부의금 입력'!$D$2:$D$1001,MATCH($A36,'부의금 입력'!$H$2:$H$1001,0))&"") | E36: =IF($A36="","",INDEX('부의금 입력'!$E$2:$E$1001,MATCH($A36,'부의금 입력'!$H$2:$H$1001,0))&"") | H36: =IF(33>$I$1,"",INDEX('근조 화환'!$B$2:$B$501,MATCH(33,'근조 화환'!$G$2:$G$501,0))&"") | I36: =IF(33>$I$1,"",INDEX('근조 화환'!$C$2:$C$501,MATCH(33,'근조 화환'!$G$2:$G$501,0))&"") | J36: =IF(33>$I$1,"",INDEX('근조 화환'!$D$2:$D$501,MATCH(33,'근조 화환'!$G$2:$G$501,0))&"") | K36: =IF(33>$I$1,"",INDEX('근조 화환'!$E$2:$E$501,MATCH(33,'근조 화환'!$G$2:$G$501,0))&"")
A37: =IF(34<=$F$1,34,"") | B37: =IF($A37="","",INDEX('부의금 입력'!$B$2:$B$1001,MATCH($A37,'부의금 입력'!$H$2:$H$1001,0))&"") | C37: =IF($A37="","",INDEX('부의금 입력'!$C$2:$C$1001,MATCH($A37,'부의금 입력'!$H$2:$H$1001,0))) | D37: =IF($A37="","",INDEX('부의금 입력'!$D$2:$D$1001,MATCH($A37,'부의금 입력'!$H$2:$H$1001,0))&"") | E37: =IF($A37="","",INDEX('부의금 입력'!$E$2:$E$1001,MATCH($A37,'부의금 입력'!$H$2:$H$1001,0))&"") | H37: =IF(34>$I$1,"",INDEX('근조 화환'!$B$2:$B$501,MATCH(34,'근조 화환'!$G$2:$G$501,0))&"") | I37: =IF(34>$I$1,"",INDEX('근조 화환'!$C$2:$C$501,MATCH(34,'근조 화환'!$G$2:$G$501,0))&"") | J37: =IF(34>$I$1,"",INDEX('근조 화환'!$D$2:$D$501,MATCH(34,'근조 화환'!$G$2:$G$501,0))&"") | K37: =IF(34>$I$1,"",INDEX('근조 화환'!$E$2:$E$501,MATCH(34,'근조 화환'!$G$2:$G$501,0))&"")
A38: =IF(35<=$F$1,35,"") | B38: =IF($A38="","",INDEX('부의금 입력'!$B$2:$B$1001,MATCH($A38,'부의금 입력'!$H$2:$H$1001,0))&"") | C38: =IF($A38="","",INDEX('부의금 입력'!$C$2:$C$1001,MATCH($A38,'부의금 입력'!$H$2:$H$1001,0))) | D38: =IF($A38="","",INDEX('부의금 입력'!$D$2:$D$1001,MATCH($A38,'부의금 입력'!$H$2:$H$1001,0))&"") | E38: =IF($A38="","",INDEX('부의금 입력'!$E$2:$E$1001,MATCH($A38,'부의금 입력'!$H$2:$H$1001,0))&"") | H38: =IF(35>$I$1,"",INDEX('근조 화환'!$B$2:$B$501,MATCH(35,'근조 화환'!$G$2:$G$501,0))&"") | I38: =IF(35>$I$1,"",INDEX('근조 화환'!$C$2:$C$501,MATCH(35,'근조 화환'!$G$2:$G$501,0))&"") | J38: =IF(35>$I$1,"",INDEX('근조 화환'!$D$2:$D$501,MATCH(35,'근조 화환'!$G$2:$G$501,0))&"") | K38: =IF(35>$I$1,"",INDEX('근조 화환'!$E$2:$E$501,MATCH(35,'근조 화환'!$G$2:$G$501,0))&"")
A39: =IF(36<=$F$1,36,"") | B39: =IF($A39="","",INDEX('부의금 입력'!$B$2:$B$1001,MATCH($A39,'부의금 입력'!$H$2:$H$1001,0))&"") | C39: =IF($A39="","",INDEX('부의금 입력'!$C$2:$C$1001,MATCH($A39,'부의금 입력'!$H$2:$H$1001,0))) | D39: =IF($A39="","",INDEX('부의금 입력'!$D$2:$D$1001,MATCH($A39,'부의금 입력'!$H$2:$H$1001,0))&"") | E39: =IF($A39="","",INDEX('부의금 입력'!$E$2:$E$1001,MATCH($A39,'부의금 입력'!$H$2:$H$1001,0))&"") | H39: =IF(36>$I$1,"",INDEX('근조 화환'!$B$2:$B$501,MATCH(36,'근조 화환'!$G$2:$G$501,0))&"") | I39: =IF(36>$I$1,"",INDEX('근조 화환'!$C$2:$C$501,MATCH(36,'근조 화환'!$G$2:$G$501,0))&"") | J39: =IF(36>$I$1,"",INDEX('근조 화환'!$D$2:$D$501,MATCH(36,'근조 화환'!$G$2:$G$501,0))&"") | K39: =IF(36>$I$1,"",INDEX('근조 화환'!$E$2:$E$501,MATCH(36,'근조 화환'!$G$2:$G$501,0))&"")
A40: =IF(37<=$F$1,37,"") | B40: =IF($A40="","",INDEX('부의금 입력'!$B$2:$B$1001,MATCH($A40,'부의금 입력'!$H$2:$H$1001,0))&"") | C40: =IF($A40="","",INDEX('부의금 입력'!$C$2:$C$1001,MATCH($A40,'부의금 입력'!$H$2:$H$1001,0))) | D40: =IF($A40="","",INDEX('부의금 입력'!$D$2:$D$1001,MATCH($A40,'부의금 입력'!$H$2:$H$1001,0))&"") | E40: =IF($A40="","",INDEX('부의금 입력'!$E$2:$E$1001,MATCH($A40,'부의금 입력'!$H$2:$H$1001,0))&"") | H40: =IF(37>$I$1,"",INDEX('근조 화환'!$B$2:$B$501,MATCH(37,'근조 화환'!$G$2:$G$501,0))&"") | I40: =IF(37>$I$1,"",INDEX('근조 화환'!$C$2:$C$501,MATCH(37,'근조 화환'!$G$2:$G$501,0))&"") | J40: =IF(37>$I$1,"",INDEX('근조 화환'!$D$2:$D$501,MATCH(37,'근조 화환'!$G$2:$G$501,0))&"") | K40: =IF(37>$I$1,"",INDEX('근조 화환'!$E$2:$E$501,MATCH(37,'근조 화환'!$G$2:$G$501,0))&"")
...

Sheet 물품 통계
A1: 조화·물품 통계
A4: 종류 | B4: 개수 | C4: 비중 | E4: 받은 가족 | F4: 근조화환 | G4: 근조 바구니 | H4: 근조기 | I4: 쌀화환 | J4: 기타 | K4: 합계
A5: 근조화환 | B5: =COUNTIF('근조 화환'!$C$2:$C$501,A5) | C5: =IF(요약!$E$1=0,0,B5/요약!$E$1) | E5: =IF('가족 목록'!A2="","",'가족 목록'!A2) | F5: =IF($E5="","",COUNTIFS('근조 화환'!$A$2:$A$501,$E5,'근조 화환'!$C$2:$C$501,"근조화환")) | G5: =IF($E5="","",COUNTIFS('근조 화환'!$A$2:$A$501,$E5,'근조 화환'!$C$2:$C$501,"근조 바구니")) | H5: =IF($E5="","",COUNTIFS('근조 화환'!$A$2:$A$501,$E5,'근조 화환'!$C$2:$C$501,"근조기")) | I5: =IF($E5="","",COUNTIFS('근조 화환'!$A$2:$A$501,$E5,'근조 화환'!$C$2:$C$501,"쌀화환")) | J5: =IF($E5="","",COUNTIFS('근조 화환'!$A$2:$A$501,$E5,'근조 화환'!$C$2:$C$501,"기타")) | K5: =IF($E5="","",COUNTIF('근조 화환'!$A$2:$A$501,$E5))
A6: 근조 바구니 | B6: =COUNTIF('근조 화환'!$C$2:$C$501,A6) | C6: =IF(요약!$E$1=0,0,B6/요약!$E$1) | E6: =IF('가족 목록'!A3="","",'가족 목록'!A3) | F6: =IF($E6="","",COUNTIFS('근조 화환'!$A$2:$A$501,$E6,'근조 화환'!$C$2:$C$501,"근조화환")) | G6: =IF($E6="","",COUNTIFS('근조 화환'!$A$2:$A$501,$E6,'근조 화환'!$C$2:$C$501,"근조 바구니")) | H6: =IF($E6="","",COUNTIFS('근조 화환'!$A$2:$A$501,$E6,'근조 화환'!$C$2:$C$501,"근조기")) | I6: =IF($E6="","",COUNTIFS('근조 화환'!$A$2:$A$501,$E6,'근조 화환'!$C$2:$C$501,"쌀화환")) | J6: =IF($E6="","",COUNTIFS('근조 화환'!$A$2:$A$501,$E6,'근조 화환'!$C$2:$C$501,"기타")) | K6: =IF($E6="","",COUNTIF('근조 화환'!$A$2:$A$501,$E6))
A7: 근조기 | B7: =COUNTIF('근조 화환'!$C$2:$C$501,A7) | C7: =IF(요약!$E$1=0,0,B7/요약!$E$1) | E7: =IF('가족 목록'!A4="","",'가족 목록'!A4) | F7: =IF($E7="","",COUNTIFS('근조 화환'!$A$2:$A$501,$E7,'근조 화환'!$C$2:$C$501,"근조화환")) | G7: =IF($E7="","",COUNTIFS('근조 화환'!$A$2:$A$501,$E7,'근조 화환'!$C$2:$C$501,"근조 바구니")) | H7: =IF($E7="","",COUNTIFS('근조 화환'!$A$2:$A$501,$E7,'근조 화환'!$C$2:$C$501,"근조기")) | I7: =IF($E7="","",COUNTIFS('근조 화환'!$A$2:$A$501,$E7,'근조 화환'!$C$2:$C$501,"쌀화환")) | J7: =IF($E7="","",COUNTIFS('근조 화환'!$A$2:$A$501,$E7,'근조 화환'!$C$2:$C$501,"기타")) | K7: =IF($E7="","",COUNTIF('근조 화환'!$A$2:$A$501,$E7))
A8: 쌀화환 | B8: =COUNTIF('근조 화환'!$C$2:$C$501,A8) | C8: =IF(요약!$E$1=0,0,B8/요약!$E$1) | E8: =IF('가족 목록'!A5="","",'가족 목록'!A5) | F8: =IF($E8="","",COUNTIFS('근조 화환'!$A$2:$A$501,$E8,'근조 화환'!$C$2:$C$501,"근조화환")) | G8: =IF($E8="","",COUNTIFS('근조 화환'!$A$2:$A$501,$E8,'근조 화환'!$C$2:$C$501,"근조 바구니")) | H8: =IF($E8="","",COUNTIFS('근조 화환'!$A$2:$A$501,$E8,'근조 화환'!$C$2:$C$501,"근조기")) | I8: =IF($E8="","",COUNTIFS('근조 화환'!$A$2:$A$501,$E8,'근조 화환'!$C$2:$C$501,"쌀화환")) | J8: =IF($E8="","",COUNTIFS('근조 화환'!$A$2:$A$501,$E8,'근조 화환'!$C$2:$C$501,"기타")) | K8: =IF($E8="","",COUNTIF('근조 화환'!$A$2:$A$501,$E8))
A9: 기타 | B9: =COUNTIF('근조 화환'!$C$2:$C$501,A9) | C9: =IF(요약!$E$1=0,0,B9/요약!$E$1) | E9: =IF('가족 목록'!A6="","",'가족 목록'!A6) | F9: =IF($E9="","",COUNTIFS('근조 화환'!$A$2:$A$501,$E9,'근조 화환'!$C$2:$C$501,"근조화환")) | G9: =IF($E9="","",COUNTIFS('근조 화환'!$A$2:$A$501,$E9,'근조 화환'!$C$2:$C$501,"근조 바구니")) | H9: =IF($E9="","",COUNTIFS('근조 화환'!$A$2:$A$501,$E9,'근조 화환'!$C$2:$C$501,"근조기")) | I9: =IF($E9="","",COUNTIFS('근조 화환'!$A$2:$A$501,$E9,'근조 화환'!$C$2:$C$501,"쌀화환")) | J9: =IF($E9="","",COUNTIFS('근조 화환'!$A$2:$A$501,$E9,'근조 화환'!$C$2:$C$501,"기타")) | K9: =IF($E9="","",COUNTIF('근조 화환'!$A$2:$A$501,$E9))
A10: 그 밖 | B10: =요약!E1-SUM(B5:B9) | C10: =IF(요약!$E$1=0,0,B10/요약!$E$1) | E10: =IF('가족 목록'!A7="","",'가족 목록'!A7) | F10: =IF($E10="","",COUNTIFS('근조 화환'!$A$2:$A$501,$E10,'근조 화환'!$C$2:$C$501,"근조화환")) | G10: =IF($E10="","",COUNTIFS('근조 화환'!$A$2:$A$501,$E10,'근조 화환'!$C$2:$C$501,"근조 바구니")) | H10: =IF($E10="","",COUNTIFS('근조 화환'!$A$2:$A$501,$E10,'근조 화환'!$C$2:$C$501,"근조기")) | I10: =IF($E10="","",COUNTIFS('근조 화환'!$A$2:$A$501,$E10,'근조 화환'!$C$2:$C$501,"쌀화환")) | J10: =IF($E10="","",COUNTIFS('근조 화환'!$A$2:$A$501,$E10,'근조 화환'!$C$2:$C$501,"기타")) | K10: =IF($E10="","",COUNTIF('근조 화환'!$A$2:$A$501,$E10))
E11: =IF('가족 목록'!A8="","",'가족 목록'!A8) | F11: =IF($E11="","",COUNTIFS('근조 화환'!$A$2:$A$501,$E11,'근조 화환'!$C$2:$C$501,"근조화환")) | G11: =IF($E11="","",COUNTIFS('근조 화환'!$A$2:$A$501,$E11,'근조 화환'!$C$2:$C$501,"근조 바구니")) | H11: =IF($E11="","",COUNTIFS('근조 화환'!$A$2:$A$501,$E11,'근조 화환'!$C$2:$C$501,"근조기")) | I11: =IF($E11="","",COUNTIFS('근조 화환'!$A$2:$A$501,$E11,'근조 화환'!$C$2:$C$501,"쌀화환")) | J11: =IF($E11="","",COUNTIFS('근조 화환'!$A$2:$A$501,$E11,'근조 화환'!$C$2:$C$501,"기타")) | K11: =IF($E11="","",COUNTIF('근조 화환'!$A$2:$A$501,$E11))
E12: =IF('가족 목록'!A9="","",'가족 목록'!A9) | F12: =IF($E12="","",COUNTIFS('근조 화환'!$A$2:$A$501,$E12,'근조 화환'!$C$2:$C$501,"근조화환")) | G12: =IF($E12="","",COUNTIFS('근조 화환'!$A$2:$A$501,$E12,'근조 화환'!$C$2:$C$501,"근조 바구니")) | H12: =IF($E12="","",COUNTIFS('근조 화환'!$A$2:$A$501,$E12,'근조 화환'!$C$2:$C$501,"근조기")) | I12: =IF($E12="","",COUNTIFS('근조 화환'!$A$2:$A$501,$E12,'근조 화환'!$C$2:$C$501,"쌀화환")) | J12: =IF($E12="","",COUNTIFS('근조 화환'!$A$2:$A$501,$E12,'근조 화환'!$C$2:$C$501,"기타")) | K12: =IF($E12="","",COUNTIF('근조 화환'!$A$2:$A$501,$E12))
E13: =IF('가족 목록'!A10="","",'가족 목록'!A10) | F13: =IF($E13="","",COUNTIFS('근조 화환'!$A$2:$A$501,$E13,'근조 화환'!$C$2:$C$501,"근조화환")) | G13: =IF($E13="","",COUNTIFS('근조 화환'!$A$2:$A$501,$E13,'근조 화환'!$C$2:$C$501,"근조 바구니")) | H13: =IF($E13="","",COUNTIFS('근조 화환'!$A$2:$A$501,$E13,'근조 화환'!$C$2:$C$501,"근조기")) | I13: =IF($E13="","",COUNTIFS('근조 화환'!$A$2:$A$501,$E13,'근조 화환'!$C$2:$C$501,"쌀화환")) | J13: =IF($E13="","",COUNTIFS('근조 화환'!$A$2:$A$501,$E13,'근조 화환'!$C$2:$C$501,"기타")) | K13: =IF($E13="","",COUNTIF('근조 화환'!$A$2:$A$501,$E13))
E14: =IF('가족 목록'!A11="","",'가족 목록'!A11) | F14: =IF($E14="","",COUNTIFS('근조 화환'!$A$2:$A$501,$E14,'근조 화환'!$C$2:$C$501,"근조화환")) | G14: =IF($E14="","",COUNTIFS('근조 화환'!$A$2:$A$501,$E14,'근조 화환'!$C$2:$C$501,"근조 바구니")) | H14: =IF($E14="","",COUNTIFS('근조 화환'!$A$2:$A$501,$E14,'근조 화환'!$C$2:$C$501,"근조기")) | I14: =IF($E14="","",COUNTIFS('근조 화환'!$A$2:$A$501,$E14,'근조 화환'!$C$2:$C$501,"쌀화환")) | J14: =IF($E14="","",COUNTIFS('근조 화환'!$A$2:$A$501,$E14,'근조 화환'!$C$2:$C$501,"기타")) | K14: =IF($E14="","",COUNTIF('근조 화환'!$A$2:$A$501,$E14))
E15: =IF('가족 목록'!A12="","",'가족 목록'!A12) | F15: =IF($E15="","",COUNTIFS('근조 화환'!$A$2:$A$501,$E15,'근조 화환'!$C$2:$C$501,"근조화환")) | G15: =IF($E15="","",COUNTIFS('근조 화환'!$A$2:$A$501,$E15,'근조 화환'!$C$2:$C$501,"근조 바구니")) | H15: =IF($E15="","",COUNTIFS('근조 화환'!$A$2:$A$501,$E15,'근조 화환'!$C$2:$C$501,"근조기")) | I15: =IF($E15="","",COUNTIFS('근조 화환'!$A$2:$A$501,$E15,'근조 화환'!$C$2:$C$501,"쌀화환")) | J15: =IF($E15="","",COUNTIFS('근조 화환'!$A$2:$A$501,$E15,'근조 화환'!$C$2:$C$501,"기타")) | K15: =IF($E15="","",COUNTIF('근조 화환'!$A$2:$A$501,$E15))
E16: =IF('가족 목록'!A13="","",'가족 목록'!A13) | F16: =IF($E16="","",COUNTIFS('근조 화환'!$A$2:$A$501,$E16,'근조 화환'!$C$2:$C$501,"근조화환")) | G16: =IF($E16="","",COUNTIFS('근조 화환'!$A$2:$A$501,$E16,'근조 화환'!$C$2:$C$501,"근조 바구니")) | H16: =IF($E16="","",COUNTIFS('근조 화환'!$A$2:$A$501,$E16,'근조 화환'!$C$2:$C$501,"근조기")) | I16: =IF($E16="","",COUNTIFS('근조 화환'!$A$2:$A$501,$E16,'근조 화환'!$C$2:$C$501,"쌀화환")) | J16: =IF($E16="","",COUNTIFS('근조 화환'!$A$2:$A$501,$E16,'근조 화환'!$C$2:$C$501,"기타")) | K16: =IF($E16="","",COUNTIF('근조 화환'!$A$2:$A$501,$E16))
E17: =IF('가족 목록'!A14="","",'가족 목록'!A14) | F17: =IF($E17="","",COUNTIFS('근조 화환'!$A$2:$A$501,$E17,'근조 화환'!$C$2:$C$501,"근조화환")) | G17: =IF($E17="","",COUNTIFS('근조 화환'!$A$2:$A$501,$E17,'근조 화환'!$C$2:$C$501,"근조 바구니")) | H17: =IF($E17="","",COUNTIFS('근조 화환'!$A$2:$A$501,$E17,'근조 화환'!$C$2:$C$501,"근조기")) | I17: =IF($E17="","",COUNTIFS('근조 화환'!$A$2:$A$501,$E17,'근조 화환'!$C$2:$C$501,"쌀화환")) | J17: =IF($E17="","",COUNTIFS('근조 화환'!$A$2:$A$501,$E17,'근조 화환'!$C$2:$C$501,"기타")) | K17: =IF($E17="","",COUNTIF('근조 화환'!$A$2:$A$501,$E17))
E18: =IF('가족 목록'!A15="","",'가족 목록'!A15) | F18: =IF($E18="","",COUNTIFS('근조 화환'!$A$2:$A$501,$E18,'근조 화환'!$C$2:$C$501,"근조화환")) | G18: =IF($E18="","",COUNTIFS('근조 화환'!$A$2:$A$501,$E18,'근조 화환'!$C$2:$C$501,"근조 바구니")) | H18: =IF($E18="","",COUNTIFS('근조 화환'!$A$2:$A$501,$E18,'근조 화환'!$C$2:$C$501,"근조기")) | I18: =IF($E18="","",COUNTIFS('근조 화환'!$A$2:$A$501,$E18,'근조 화환'!$C$2:$C$501,"쌀화환")) | J18: =IF($E18="","",COUNTIFS('근조 화환'!$A$2:$A$501,$E18,'근조 화환'!$C$2:$C$501,"기타")) | K18: =IF($E18="","",COUNTIF('근조 화환'!$A$2:$A$501,$E18))
E19: =IF('가족 목록'!A16="","",'가족 목록'!A16) | F19: =IF($E19="","",COUNTIFS('근조 화환'!$A$2:$A$501,$E19,'근조 화환'!$C$2:$C$501,"근조화환")) | G19: =IF($E19="","",COUNTIFS('근조 화환'!$A$2:$A$501,$E19,'근조 화환'!$C$2:$C$501,"근조 바구니")) | H19: =IF($E19="","",COUNTIFS('근조 화환'!$A$2:$A$501,$E19,'근조 화환'!$C$2:$C$501,"근조기")) | I19: =IF($E19="","",COUNTIFS('근조 화환'!$A$2:$A$501,$E19,'근조 화환'!$C$2:$C$501,"쌀화환")) | J19: =IF($E19="","",COUNTIFS('근조 화환'!$A$2:$A$501,$E19,'근조 화환'!$C$2:$C$501,"기타")) | K19: =IF($E19="","",COUNTIF('근조 화환'!$A$2:$A$501,$E19))
E20: =IF('가족 목록'!A17="","",'가족 목록'!A17) | F20: =IF($E20="","",COUNTIFS('근조 화환'!$A$2:$A$501,$E20,'근조 화환'!$C$2:$C$501,"근조화환")) | G20: =IF($E20="","",COUNTIFS('근조 화환'!$A$2:$A$501,$E20,'근조 화환'!$C$2:$C$501,"근조 바구니")) | H20: =IF($E20="","",COUNTIFS('근조 화환'!$A$2:$A$501,$E20,'근조 화환'!$C$2:$C$501,"근조기")) | I20: =IF($E20="","",COUNTIFS('근조 화환'!$A$2:$A$501,$E20,'근조 화환'!$C$2:$C$501,"쌀화환")) | J20: =IF($E20="","",COUNTIFS('근조 화환'!$A$2:$A$501,$E20,'근조 화환'!$C$2:$C$501,"기타")) | K20: =IF($E20="","",COUNTIF('근조 화환'!$A$2:$A$501,$E20))
E21: =IF('가족 목록'!A18="","",'가족 목록'!A18) | F21: =IF($E21="","",COUNTIFS('근조 화환'!$A$2:$A$501,$E21,'근조 화환'!$C$2:$C$501,"근조화환")) | G21: =IF($E21="","",COUNTIFS('근조 화환'!$A$2:$A$501,$E21,'근조 화환'!$C$2:$C$501,"근조 바구니")) | H21: =IF($E21="","",COUNTIFS('근조 화환'!$A$2:$A$501,$E21,'근조 화환'!$C$2:$C$501,"근조기")) | I21: =IF($E21="","",COUNTIFS('근조 화환'!$A$2:$A$501,$E21,'근조 화환'!$C$2:$C$501,"쌀화환")) | J21: =IF($E21="","",COUNTIFS('근조 화환'!$A$2:$A$501,$E21,'근조 화환'!$C$2:$C$501,"기타")) | K21: =IF($E21="","",COUNTIF('근조 화환'!$A$2:$A$501,$E21))
E22: =IF('가족 목록'!A19="","",'가족 목록'!A19) | F22: =IF($E22="","",COUNTIFS('근조 화환'!$A$2:$A$501,$E22,'근조 화환'!$C$2:$C$501,"근조화환")) | G22: =IF($E22="","",COUNTIFS('근조 화환'!$A$2:$A$501,$E22,'근조 화환'!$C$2:$C$501,"근조 바구니")) | H22: =IF($E22="","",COUNTIFS('근조 화환'!$A$2:$A$501,$E22,'근조 화환'!$C$2:$C$501,"근조기")) | I22: =IF($E22="","",COUNTIFS('근조 화환'!$A$2:$A$501,$E22,'근조 화환'!$C$2:$C$501,"쌀화환")) | J22: =IF($E22="","",COUNTIFS('근조 화환'!$A$2:$A$501,$E22,'근조 화환'!$C$2:$C$501,"기타")) | K22: =IF($E22="","",COUNTIF('근조 화환'!$A$2:$A$501,$E22))
... E24: =IF('가족 목록'!A21="","",'가족 목록'!A21) | F24: =IF($E24="","",COUNTIFS('근조 화환'!$A$2:$A$501,$E24,'근조 화환'!$C$2:$C$501,"근조화환")) | G24: =IF($E24="","",COUNTIFS('근조 화환'!$A$2:$A$501,$E24,'근조 화환'!$C$2:$C$501,"근조 바구니")) | H24: =IF($E24="","",COUNTIFS('근조 화환'!$A$2:$A$501,$E24,'근조 화환'!$C$2:$C$501,"근조기")) | I24: =IF($E24="","",COUNTIFS('근조 화환'!$A$2:$A$501,$E24,'근조 화환'!$C$2:$C$501,"쌀화환")) | J24: =IF($E24="","",COUNTIFS('근조 화환'!$A$2:$A$501,$E24,'근조 화환'!$C$2:$C$501,"기타")) | K24: =IF($E24="","",COUNTIF('근조 화환'!$A$2:$A$501,$E24))

Sheet 가족 목록
A1: 받은 가족 | B1: 정산 참여 | D1: 부의금·화환을 받는 가족 이름을 적으세요. 여기 적은 이름이 드롭다운과 요약에 나옵니다.
D2: 정산 참여: 장례 비용을 나눠 낼 가족은 비워 두거나 O, 빠질 가족(예: 손주)은 X.

Sheet 부의금 입력
A1: 받은 가족 | B1: 이름 | C1: 금액 | D1: 소속·관계 | E1: 메모 | F1: 확인 필요 | G1: 일차 (자동) | H1: 가족별 순번 | I1: 소계 번호 | J1: 확인 표시
F2: =IF(COUNTA(A2:E2)=0,"",IF(OR(ISNUMBER(SEARCH("소계",B2)),ISNUMBER(SEARCH("합계",B2))),"",TRIM(IF(B2="","이름 없음 ","")&IF(A2="","받은 가족 없음 ","")&IF(C2="","금액 없음 ",IF(ISNUMBER(C2),IF(C2<1000,"금액 확인 ",""),"금액 확인 "))&IF(AND(B2<>"",COUNTIFS($A$2:$A$1001,A2,$B$2:$B$1001,B2,$C$2:$C$1001,C2)>1),"중복 의심","")))) | G2: =IF(OR(COUNTA(A2:E2)=0,OR(ISNUMBER(SEARCH("소계",B2)),ISNUMBER(SEARCH("합계",B2)))),"",1+COUNTIF($B$1:B1,"*소계*")) | H2: =IF(AND(A2<>"",A2=가족별!$B$1,G2<>""),COUNTIFS($A$2:A2,가족별!$B$1,$G$2:G2,">0"),"") | I2: =IF(ISNUMBER(SEARCH("소계",B2)),COUNTIF($B$2:B2,"*소계*"),"") | J2: =IF(F2="",0,1)
F3: =IF(COUNTA(A3:E3)=0,"",IF(OR(ISNUMBER(SEARCH("소계",B3)),ISNUMBER(SEARCH("합계",B3))),"",TRIM(IF(B3="","이름 없음 ","")&IF(A3="","받은 가족 없음 ","")&IF(C3="","금액 없음 ",IF(ISNUMBER(C3),IF(C3<1000,"금액 확인 ",""),"금액 확인 "))&IF(AND(B3<>"",COUNTIFS($A$2:$A$1001,A3,$B$2:$B$1001,B3,$C$2:$C$1001,C3)>1),"중복 의심","")))) | G3: =IF(OR(COUNTA(A3:E3)=0,OR(ISNUMBER(SEARCH("소계",B3)),ISNUMBER(SEARCH("합계",B3)))),"",1+COUNTIF($B$1:B2,"*소계*")) | H3: =IF(AND(A3<>"",A3=가족별!$B$1,G3<>""),COUNTIFS($A$2:A3,가족별!$B$1,$G$2:G3,">0"),"") | I3: =IF(ISNUMBER(SEARCH("소계",B3)),COUNTIF($B$2:B3,"*소계*"),"") | J3: =IF(F3="",0,1)
F4: =IF(COUNTA(A4:E4)=0,"",IF(OR(ISNUMBER(SEARCH("소계",B4)),ISNUMBER(SEARCH("합계",B4))),"",TRIM(IF(B4="","이름 없음 ","")&IF(A4="","받은 가족 없음 ","")&IF(C4="","금액 없음 ",IF(ISNUMBER(C4),IF(C4<1000,"금액 확인 ",""),"금액 확인 "))&IF(AND(B4<>"",COUNTIFS($A$2:$A$1001,A4,$B$2:$B$1001,B4,$C$2:$C$1001,C4)>1),"중복 의심","")))) | G4: =IF(OR(COUNTA(A4:E4)=0,OR(ISNUMBER(SEARCH("소계",B4)),ISNUMBER(SEARCH("합계",B4)))),"",1+COUNTIF($B$1:B3,"*소계*")) | H4: =IF(AND(A4<>"",A4=가족별!$B$1,G4<>""),COUNTIFS($A$2:A4,가족별!$B$1,$G$2:G4,">0"),"") | I4: =IF(ISNUMBER(SEARCH("소계",B4)),COUNTIF($B$2:B4,"*소계*"),"") | J4: =IF(F4="",0,1)
F5: =IF(COUNTA(A5:E5)=0,"",IF(OR(ISNUMBER(SEARCH("소계",B5)),ISNUMBER(SEARCH("합계",B5))),"",TRIM(IF(B5="","이름 없음 ","")&IF(A5="","받은 가족 없음 ","")&IF(C5="","금액 없음 ",IF(ISNUMBER(C5),IF(C5<1000,"금액 확인 ",""),"금액 확인 "))&IF(AND(B5<>"",COUNTIFS($A$2:$A$1001,A5,$B$2:$B$1001,B5,$C$2:$C$1001,C5)>1),"중복 의심","")))) | G5: =IF(OR(COUNTA(A5:E5)=0,OR(ISNUMBER(SEARCH("소계",B5)),ISNUMBER(SEARCH("합계",B5)))),"",1+COUNTIF($B$1:B4,"*소계*")) | H5: =IF(AND(A5<>"",A5=가족별!$B$1,G5<>""),COUNTIFS($A$2:A5,가족별!$B$1,$G$2:G5,">0"),"") | I5: =IF(ISNUMBER(SEARCH("소계",B5)),COUNTIF($B$2:B5,"*소계*"),"") | J5: =IF(F5="",0,1)
F6: =IF(COUNTA(A6:E6)=0,"",IF(OR(ISNUMBER(SEARCH("소계",B6)),ISNUMBER(SEARCH("합계",B6))),"",TRIM(IF(B6="","이름 없음 ","")&IF(A6="","받은 가족 없음 ","")&IF(C6="","금액 없음 ",IF(ISNUMBER(C6),IF(C6<1000,"금액 확인 ",""),"금액 확인 "))&IF(AND(B6<>"",COUNTIFS($A$2:$A$1001,A6,$B$2:$B$1001,B6,$C$2:$C$1001,C6)>1),"중복 의심","")))) | G6: =IF(OR(COUNTA(A6:E6)=0,OR(ISNUMBER(SEARCH("소계",B6)),ISNUMBER(SEARCH("합계",B6)))),"",1+COUNTIF($B$1:B5,"*소계*")) | H6: =IF(AND(A6<>"",A6=가족별!$B$1,G6<>""),COUNTIFS($A$2:A6,가족별!$B$1,$G$2:G6,">0"),"") | I6: =IF(ISNUMBER(SEARCH("소계",B6)),COUNTIF($B$2:B6,"*소계*"),"") | J6: =IF(F6="",0,1)
F7: =IF(COUNTA(A7:E7)=0,"",IF(OR(ISNUMBER(SEARCH("소계",B7)),ISNUMBER(SEARCH("합계",B7))),"",TRIM(IF(B7="","이름 없음 ","")&IF(A7="","받은 가족 없음 ","")&IF(C7="","금액 없음 ",IF(ISNUMBER(C7),IF(C7<1000,"금액 확인 ",""),"금액 확인 "))&IF(AND(B7<>"",COUNTIFS($A$2:$A$1001,A7,$B$2:$B$1001,B7,$C$2:$C$1001,C7)>1),"중복 의심","")))) | G7: =IF(OR(COUNTA(A7:E7)=0,OR(ISNUMBER(SEARCH("소계",B7)),ISNUMBER(SEARCH("합계",B7)))),"",1+COUNTIF($B$1:B6,"*소계*")) | H7: =IF(AND(A7<>"",A7=가족별!$B$1,G7<>""),COUNTIFS($A$2:A7,가족별!$B$1,$G$2:G7,">0"),"") | I7: =IF(ISNUMBER(SEARCH("소계",B7)),COUNTIF($B$2:B7,"*소계*"),"") | J7: =IF(F7="",0,1)
F8: =IF(COUNTA(A8:E8)=0,"",IF(OR(ISNUMBER(SEARCH("소계",B8)),ISNUMBER(SEARCH("합계",B8))),"",TRIM(IF(B8="","이름 없음 ","")&IF(A8="","받은 가족 없음 ","")&IF(C8="","금액 없음 ",IF(ISNUMBER(C8),IF(C8<1000,"금액 확인 ",""),"금액 확인 "))&IF(AND(B8<>"",COUNTIFS($A$2:$A$1001,A8,$B$2:$B$1001,B8,$C$2:$C$1001,C8)>1),"중복 의심","")))) | G8: =IF(OR(COUNTA(A8:E8)=0,OR(ISNUMBER(SEARCH("소계",B8)),ISNUMBER(SEARCH("합계",B8)))),"",1+COUNTIF($B$1:B7,"*소계*")) | H8: =IF(AND(A8<>"",A8=가족별!$B$1,G8<>""),COUNTIFS($A$2:A8,가족별!$B$1,$G$2:G8,">0"),"") | I8: =IF(ISNUMBER(SEARCH("소계",B8)),COUNTIF($B$2:B8,"*소계*"),"") | J8: =IF(F8="",0,1)
F9: =IF(COUNTA(A9:E9)=0,"",IF(OR(ISNUMBER(SEARCH("소계",B9)),ISNUMBER(SEARCH("합계",B9))),"",TRIM(IF(B9="","이름 없음 ","")&IF(A9="","받은 가족 없음 ","")&IF(C9="","금액 없음 ",IF(ISNUMBER(C9),IF(C9<1000,"금액 확인 ",""),"금액 확인 "))&IF(AND(B9<>"",COUNTIFS($A$2:$A$1001,A9,$B$2:$B$1001,B9,$C$2:$C$1001,C9)>1),"중복 의심","")))) | G9: =IF(OR(COUNTA(A9:E9)=0,OR(ISNUMBER(SEARCH("소계",B9)),ISNUMBER(SEARCH("합계",B9)))),"",1+COUNTIF($B$1:B8,"*소계*")) | H9: =IF(AND(A9<>"",A9=가족별!$B$1,G9<>""),COUNTIFS($A$2:A9,가족별!$B$1,$G$2:G9,">0"),"") | I9: =IF(ISNUMBER(SEARCH("소계",B9)),COUNTIF($B$2:B9,"*소계*"),"") | J9: =IF(F9="",0,1)
F10: =IF(COUNTA(A10:E10)=0,"",IF(OR(ISNUMBER(SEARCH("소계",B10)),ISNUMBER(SEARCH("합계",B10))),"",TRIM(IF(B10="","이름 없음 ","")&IF(A10="","받은 가족 없음 ","")&IF(C10="","금액 없음 ",IF(ISNUMBER(C10),IF(C10<1000,"금액 확인 ",""),"금액 확인 "))&IF(AND(B10<>"",COUNTIFS($A$2:$A$1001,A10,$B$2:$B$1001,B10,$C$2:$C$1001,C10)>1),"중복 의심","")))) | G10: =IF(OR(COUNTA(A10:E10)=0,OR(ISNUMBER(SEARCH("소계",B10)),ISNUMBER(SEARCH("합계",B10)))),"",1+COUNTIF($B$1:B9,"*소계*")) | H10: =IF(AND(A10<>"",A10=가족별!$B$1,G10<>""),COUNTIFS($A$2:A10,가족별!$B$1,$G$2:G10,">0"),"") | I10: =IF(ISNUMBER(SEARCH("소계",B10)),COUNTIF($B$2:B10,"*소계*"),"") | J10: =IF(F10="",0,1)
